<?xml version="1.0" encoding="utf-8"?>
<!-- This URDF was automatically created by SolidWorks to URDF Exporter! Originally created by Stephen Brawner (brawner@gmail.com) 
     Commit Version: 1.6.0-4-g7f85cfe  Build Version: 1.6.7995.38578
     For more information, please see http://wiki.ros.org/sw_urdf_exporter -->

<robot name="q2">
  <mujoco>
    <compiler meshdir="meshes" discardvisual="false" balanceinertia= "true"/>
  </mujoco>
    <!-- [CAUTION] uncomment when convert to mujoco -->
  <!-- <link name="world"></link>
    <joint name="floating_base_joint" type="floating">
      <parent link="world"/>
      <child link="pelvis"/>
    </joint> -->
  
  <link name="pelvis">
    <inertial>
      <origin xyz="0.0000000 0.0000000 -0.0377830" rpy="0 0 0" />
      <mass value="5.0175069" />
      <inertia ixx="0.0180892" ixy="-0.0000001" ixz="0.0000000" iyy="0.0164150" iyz="0.0000000" izz="0.0108703" />
    </inertial>
    <visual>
      <origin xyz="0 0 0" rpy="0 0 0" />
      <geometry>
        <mesh filename="meshes/pelvis.STL" />
      </geometry>
      <material name="">
        <color rgba="0.75294 0.75294 0.75294 1" />
      </material>
    </visual>
    <collision>
      <origin xyz="0 0 0" rpy="0 0 0" />
      <geometry>
        <mesh filename="meshes/pelvis.STL" />
      </geometry>
    </collision>
  </link>
  <link name="left_hip_pitch_link">
    <inertial>
      <origin xyz="-0.0161091 0.0642172 0.0000000" rpy="0 0 0" />
      <mass value="1.871603" />
      <inertia ixx="0.0035823" ixy="0.0000353" ixz="-0.0000001" iyy="0.0021368" iyz="-0.0000023" izz="0.0024927" />
    </inertial>
    <visual>
      <origin xyz="0 0 0" rpy="0 0 0" />
      <geometry>
        <mesh filename="meshes/left_hip_pitch_link.STL" />
      </geometry>
      <material name="">
        <color rgba="0.89804 0.91765 0.92941 1" />
      </material>
    </visual>
    <collision>
      <origin xyz="0 0 0" rpy="0 0 0" />
      <geometry>
        <mesh filename="meshes/left_hip_pitch_link.STL" />
      </geometry>
    </collision>
  </link>
  <joint name="left_hip_pitch_joint" type="revolute">
    <origin xyz="0 0.056 -0.0685" rpy="0 0 0" />
    <parent link="pelvis" />
    <child link="left_hip_pitch_link" />
    <axis xyz="0 1 0" />
    <limit lower="-2.35" upper="2.35" effort="88" velocity="30" />
  </joint>
  <link name="left_hip_roll_link">
    <inertial>
      <origin xyz="-0.0070439 -0.0000032 -0.0909871" rpy="0 0 0" />
      <mass value="2.1194499" />
      <inertia ixx="0.0063862" ixy="0.0000000" ixz="-0.0009050" iyy="0.0063266" iyz="0.0000001" izz="0.0036912" />
    </inertial>
    <visual>
      <origin xyz="0 0 0" rpy="0 0 0" />
      <geometry>
        <mesh filename="meshes/left_hip_roll_link.STL" />
      </geometry>
      <material name="">
        <color rgba="0.11373 0.11373 0.11373 1" />
      </material>
    </visual>
    <!-- <collision>
      <origin
        xyz="0 0 0"
        rpy="0 0 0" />
      <geometry>
        <mesh
          filename="meshes/left_hip_roll_link.STL" />
      </geometry>
    </collision> -->
    
  </link>
  <joint name="left_hip_roll_joint" type="revolute">
    <origin xyz="0.012 0.069 0" rpy="0 0 0" />
    <parent link="left_hip_pitch_link" />
    <child link="left_hip_roll_link" />
    <axis xyz="1 0 0" />
    <limit lower="-0.43" upper="2.9" effort="88" velocity="30" />
  </joint>
  <link name="left_hip_yaw_link">
    <inertial>
      <origin xyz="0.0030582 -0.0028146 -0.1280729" rpy="0 0 0" />
      <mass value="2.4878491" />
      <inertia ixx="0.0107399" ixy="0.0000195" ixz="-0.0002983" iyy="0.0117862" iyz="-0.0001408" izz="0.0038670" />
    </inertial>
    <visual>
      <origin xyz="0 0 0" rpy="0 0 0" />
      <geometry>
        <mesh filename="meshes/left_hip_yaw_link.STL" />
      </geometry>
      <material name="">
        <color rgba="0.89804 0.91765 0.92941 1" />
      </material>
    </visual>
    <collision>
      <origin xyz="0 0 0" rpy="0 0 0" />
      <geometry>
        <mesh filename="meshes/left_hip_yaw_link.STL" />
      </geometry>
    </collision>
  </link>
  <joint name="left_hip_yaw_joint" type="revolute">
    <origin xyz="-0.012 0 -0.1395" rpy="0 0 0" />
    <parent link="left_hip_roll_link" />
    <child link="left_hip_yaw_link" />
    <axis xyz="0 0 1" />
    <limit lower="-2.8" upper="2.8" effort="88" velocity="30" />
  </joint>
  <link name="left_knee_link">
    <inertial>
      <origin xyz="0.0016871 -0.0202758 -0.1209121" rpy="0 0 0" />
      <mass value="2.1687705" />
      <inertia ixx="0.0161842" ixy="0.0000620" ixz="0.0003116" iyy="0.0144942" iyz="-0.0012327" izz="0.0039929" />
    </inertial>
    <visual>
      <origin xyz="0 0 0" rpy="0 0 0" />
      <geometry>
        <mesh filename="meshes/left_knee_link.STL" />
      </geometry>
      <material name="">
        <color rgba="0.79216 0.81961 0.93333 1" />
      </material>
    </visual>
    <!-- <collision>
      <origin
        xyz="0 0 0"
        rpy="0 0 0" />
      <geometry>
        <mesh
          filename="meshes/left_knee_link.STL" />
      </geometry>
    </collision> -->
    
  </link>
  <joint name="left_knee_joint" type="revolute">
    <origin xyz="0 0.0255 -0.1605" rpy="0 0 0" />
    <parent link="left_hip_yaw_link" />
    <child link="left_knee_link" />
    <axis xyz="0 1 0" />
    <limit lower="-0.26" upper="2.05" effort="100" velocity="30" />
  </joint>
  <link name="left_ankle_pitch_link">
    <inertial>
      <origin xyz="0.0000000 0.0000000 0.0000279" rpy="0 0 0" />
      <mass value="0.0312897" />
      <inertia ixx="0.0000068" ixy="0.0000000" ixz="0.0000000" iyy="0.0000016" iyz="0.0000000" izz="0.0000073" />
    </inertial>
    <visual>
      <origin xyz="0 0 0" rpy="0 0 0" />
      <geometry>
        <mesh filename="meshes/left_ankle_pitch_link.STL" />
      </geometry>
      <material name="">
        <color rgba="0.89804 0.91765 0.92941 1" />
      </material>
    </visual>
    <collision>
      <origin xyz="0 0 0" rpy="0 0 0" />
      <geometry>
        <mesh filename="meshes/left_ankle_pitch_link.STL" />
      </geometry>
    </collision>
  </link>
  <joint name="left_ankle_pitch_joint" type="revolute">
    <origin xyz="0 -0.0255 -0.35" rpy="0 0 0" />
    <parent link="left_knee_link" />
    <child link="left_ankle_pitch_link" />
    <axis xyz="0 1 0" />
    <limit lower="-0.6" upper="0.5" effort="15" velocity="30" />
  </joint>
  <link name="left_ankle_roll_link">
    <inertial>
      <origin xyz="0.0300502 0.0000000 -0.0348065" rpy="0 0 0" />
      <mass value="0.445514" />
      <inertia ixx="0.0001691" ixy="0.0000000" ixz="0.0000581" iyy="0.0007648" iyz="0.0000000" izz="0.0007313" />
    </inertial>
    <visual>
      <origin xyz="0 0 0" rpy="0 0 0" />
      <geometry>
        <mesh filename="meshes/left_ankle_roll_link.STL" />
      </geometry>
      <material name="">
        <color rgba="0.89804 0.91765 0.92941 1" />
      </material>
    </visual>
    <collision>
      <origin xyz="0 0 0" rpy="0 0 0" />
      <geometry>
        <mesh filename="meshes/left_ankle_roll_link.STL" />
      </geometry>
    </collision>
  </link>
  <joint name="left_ankle_roll_joint" type="revolute">
    <origin xyz="0 0 0" rpy="0 0 0" />
    <parent link="left_ankle_pitch_link" />
    <child link="left_ankle_roll_link" />
    <axis xyz="1 0 0" />
    <limit lower="-0.25" upper="0.25" effort="15" velocity="30" />
  </joint>
  <link name="right_hip_pitch_link">
    <inertial>
      <origin xyz="-0.0161085 -0.0642181 0.0000000" rpy="0 0 0" />
      <mass value="1.8719556" />
      <inertia ixx="0.0035829" ixy="-0.0000353" ixz="0.0000001" iyy="0.0021371" iyz="-0.0000023" izz="0.0024930" />
    </inertial>
    <visual>
      <origin xyz="0 0 0" rpy="0 0 0" />
      <geometry>
        <mesh filename="meshes/right_hip_pitch_link.STL" />
      </geometry>
      <material name="">
        <color rgba="0.898039215686275 0.917647058823529 0.929411764705882 1" />
      </material>
    </visual>
    <collision>
      <origin xyz="0 0 0" rpy="0 0 0" />
      <geometry>
        <mesh filename="meshes/right_hip_pitch_link.STL" />
      </geometry>
    </collision>
  </link>
  <joint name="right_hip_pitch_joint" type="revolute">
    <origin xyz="0 -0.056 -0.0685" rpy="0 0 0" />
    <parent link="pelvis" />
    <child link="right_hip_pitch_link" />
    <axis xyz="0 1 0" />
    <limit lower="-2.35" upper="2.35" effort="88" velocity="30" />
  </joint>
  <link name="right_hip_roll_link">
    <inertial>
      <origin xyz="-0.0070439 -0.0000032 -0.0909871" rpy="0 0 0" />
      <mass value="2.1194499" />
      <inertia ixx="0.0063862" ixy="0.0000000" ixz="-0.0009050" iyy="0.0063266" iyz="0.0000001" izz="0.0036912" />
    </inertial>
    <visual>
      <origin xyz="0 0 0" rpy="0 0 0" />
      <geometry>
        <mesh filename="meshes/right_hip_roll_link.STL" />
      </geometry>
      <material name="">
        <color rgba="0.11373 0.11373 0.11373 1" />
      </material>
    </visual>
    <!-- <collision>
      <origin
        xyz="0 0 0"
        rpy="0 0 0" />
      <geometry>
        <mesh
          filename="meshes/right_hip_roll_link.STL" />
      </geometry>
    </collision> -->
    
  </link>
  <joint name="right_hip_roll_joint" type="revolute">
    <origin xyz="0.012 -0.069 0" rpy="0 0 0" />
    <parent link="right_hip_pitch_link" />
    <child link="right_hip_roll_link" />
    <axis xyz="1 0 0" />
    <limit lower="-2.9" upper="0.43" effort="88" velocity="30" />
  </joint>
  <link name="right_hip_yaw_link">
    <inertial>
      <origin xyz="0.0030618 0.0028152 -0.1281604" rpy="0 0 0" />
      <mass value="2.4854678" />
      <inertia ixx="0.0107105" ixy="-0.0000196" ixz="-0.0002990" iyy="0.0117564" iyz="0.0001401" izz="0.0038603" />
    </inertial>
    <visual>
      <origin xyz="0 0 0" rpy="0 0 0" />
      <geometry>
        <mesh filename="meshes/right_hip_yaw_link.STL" />
      </geometry>
      <material name="">
        <color rgba="0.89804 0.91765 0.92941 1" />
      </material>
    </visual>
    <collision>
      <origin xyz="0 0 0" rpy="0 0 0" />
      <geometry>
        <mesh filename="meshes/right_hip_yaw_link.STL" />
      </geometry>
    </collision>
  </link>
  <joint name="right_hip_yaw_joint" type="revolute">
    <origin xyz="-0.012 0 -0.1395" rpy="0 0 0" />
    <parent link="right_hip_roll_link" />
    <child link="right_hip_yaw_link" />
    <axis xyz="0 0 1" />
    <limit lower="-2.8" upper="2.8" effort="88" velocity="30" />
  </joint>
  <link name="right_knee_link">
    <inertial>
      <origin xyz="0.0016703 0.0200408 -0.1207901" rpy="0 0 0" />
      <mass value="2.1688182" />
      <inertia ixx="0.0162684" ixy="0.0000173" ixz="0.0003081" iyy="0.0145337" iyz="0.0013876" izz="0.0040332" />
    </inertial>
    <visual>
      <origin xyz="0 0 0" rpy="0 0 0" />
      <geometry>
        <mesh filename="meshes/right_knee_link.STL" />
      </geometry>
      <material name="">
        <color rgba="0.79216 0.81961 0.93333 1" />
      </material>
    </visual>
    <!-- <collision>
      <origin
        xyz="0 0 0"
        rpy="0 0 0" />
      <geometry>
        <mesh
          filename="meshes/right_knee_link.STL" />
      </geometry>
    </collision> -->
    
  </link>
  <joint name="right_knee_joint" type="revolute">
    <origin xyz="0 -0.0255 -0.1605" rpy="0 0 0" />
    <parent link="right_hip_yaw_link" />
    <child link="right_knee_link" />
    <axis xyz="0 1 0" />
    <limit lower="-0.26" upper="2.05" effort="100" velocity="30" />
  </joint>
  <link name="right_ankle_pitch_link">
    <inertial>
      <origin xyz="0.0000000 0.0000000 0.0000279" rpy="0 0 0" />
      <mass value="0.0312897" />
      <inertia ixx="0.0000068" ixy="0.0000000" ixz="0.0000000" iyy="0.0000016" iyz="0.0000000" izz="0.0000073" />
    </inertial>
    <visual>
      <origin xyz="0 0 0" rpy="0 0 0" />
      <geometry>
        <mesh filename="meshes/right_ankle_pitch_link.STL" />
      </geometry>
      <material name="">
        <color rgba="0.898039215686275 0.917647058823529 0.929411764705882 1" />
      </material>
    </visual>
    <collision>
      <origin xyz="0 0 0" rpy="0 0 0" />
      <geometry>
        <mesh filename="meshes/right_ankle_pitch_link.STL" />
      </geometry>
    </collision>
  </link>
  <joint name="right_ankle_pitch_joint" type="revolute">
    <origin xyz="0 0.0255 -0.35" rpy="0 0 0" />
    <parent link="right_knee_link" />
    <child link="right_ankle_pitch_link" />
    <axis xyz="0 1 0" />
    <limit lower="-0.6" upper="0.5" effort="15" velocity="30" />
  </joint>
  <link name="right_ankle_roll_link">
    <inertial>
      <origin xyz="0.0300502 0.0000000 -0.0348065" rpy="0 0 0" />
      <mass value="0.445514" />
      <inertia ixx="0.0001691" ixy="0.0000000" ixz="0.0000581" iyy="0.0007648" iyz="0.0000000" izz="0.0007313" />
    </inertial>
    <visual>
      <origin xyz="0 0 0" rpy="0 0 0" />
      <geometry>
        <mesh filename="meshes/right_ankle_roll_link.STL" />
      </geometry>
      <material name="">
        <color rgba="0.89804 0.91765 0.92941 1" />
      </material>
    </visual>
    <collision>
      <origin xyz="0 0 0" rpy="0 0 0" />
      <geometry>
        <mesh filename="meshes/right_ankle_roll_link.STL" />
      </geometry>
    </collision>
  </link>
  <joint name="right_ankle_roll_joint" type="revolute">
    <origin xyz="0 0 0" rpy="0 0 0" />
    <parent link="right_ankle_pitch_link" />
    <child link="right_ankle_roll_link" />
    <axis xyz="1 0 0" />
    <limit lower="-0.25" upper="0.25" effort="15" velocity="30" />
  </joint>
  <link name="torso_link">
    <inertial>
      <origin xyz="0.0004629 -0.0000906 0.1938121" rpy="0 0 0" />
      <mass value="13.5166565" />
      <inertia ixx="0.2213687" ixy="-0.0002053" ixz="0.0002846" iyy="0.1979885" iyz="-0.0000201" izz="0.0923944" />
    </inertial>
    <visual>
      <origin xyz="0 0 0" rpy="0 0 0" />
      <geometry>
        <mesh filename="meshes/torso_link.STL" />
      </geometry>
      <material name="">
        <color rgba="0.75294 0.75294 0.75294 1" />
      </material>
    </visual>
    <collision>
      <origin xyz="0 0 0" rpy="0 0 0" />
      <geometry>
        <mesh filename="meshes/torso_link.STL" />
      </geometry>
    </collision>
  </link>
  <joint name="torso_joint" type="revolute">
    <origin xyz="0 0 0.046" rpy="0 0 0" />
    <parent link="pelvis" />
    <child link="torso_link" />
    <axis xyz="0 0 1" />
    <limit lower="-1.1" upper="1.1" effort="88" velocity="30" />
  </joint>
  <link name="left_shoulder_pitch_link">
    <inertial>
      <origin xyz="-0.0156870 0.0446137 0.0003011" rpy="0 0 0" />
      <mass value="0.5474344" />
      <inertia ixx="0.0002167" ixy="0.0000089" ixz="-0.0000002" iyy="0.0001337" iyz="-0.0000007" izz="0.0001874" />
    </inertial>
    <visual>
      <origin xyz="0 0 0" rpy="0 0 0" />
      <geometry>
        <mesh filename="meshes/left_shoulder_pitch_link.STL" />
      </geometry>
      <material name="">
        <color rgba="0.79216 0.81961 0.93333 1" />
      </material>
    </visual>
    <collision>
      <origin xyz="0 0 0" rpy="0 0 0" />
      <geometry>
        <mesh filename="meshes/left_shoulder_pitch_link.STL" />
      </geometry>
    </collision>
  </link>
  <joint name="left_shoulder_pitch_joint" type="revolute">
    <origin xyz="0 0.1045 0.2905" rpy="0 0 0" />
    <parent link="torso_link" />
    <child link="left_shoulder_pitch_link" />
    <axis xyz="0 1 0" />
    <limit lower="-3.14" upper="1.57" effort="50" velocity="30" />
  </joint>
  <link name="left_shoulder_roll_link">
    <inertial>
      <origin xyz="-0.0127037 -0.0001940 -0.0659292" rpy="0 0 0" />
      <mass value="0.5461248" />
      <inertia ixx="0.0004720" ixy="-0.0000003" ixz="-0.0001010" iyy="0.0004811" iyz="-0.0000016" izz="0.0001598" />
    </inertial>
    <visual>
      <origin xyz="0 0 0" rpy="0 0 0" />
      <geometry>
        <mesh filename="meshes/left_shoulder_roll_link.STL" />
      </geometry>
      <material name="">
        <color rgba="0.79216 0.81961 0.93333 1" />
      </material>
    </visual>
    <collision>
      <origin xyz="0 0 0" rpy="0 0 0" />
      <geometry>
        <mesh filename="meshes/left_shoulder_roll_link.STL" />
      </geometry>
    </collision>
  </link>
  <joint name="left_shoulder_roll_joint" type="revolute">
    <origin xyz="0.01 0.049 0" rpy="0 0 0" />
    <parent link="left_shoulder_pitch_link" />
    <child link="left_shoulder_roll_link" />
    <axis xyz="1 0 0" />
    <limit lower="-0.01" upper="3.14" effort="15" velocity="30" />
  </joint>
  <link name="left_shoulder_yaw_link">
    <inertial>
      <origin xyz="0.0032500 0.0002300 -0.1178721" rpy="0 0 0" />
      <mass value="0.7134352" />
      <inertia ixx="0.0021080" ixy="-0.0000082" ixz="-0.0000640" iyy="0.0021270" iyz="-0.0000181" izz="0.0003381" />
    </inertial>
    <visual>
      <origin xyz="0 0 0" rpy="0 0 0" />
      <geometry>
        <mesh filename="meshes/left_shoulder_yaw_link.STL" />
      </geometry>
      <material name="">
        <color rgba="0.79216 0.81961 0.93333 1" />
      </material>
    </visual>
    <collision>
      <origin xyz="0 0 0" rpy="0 0 0" />
      <geometry>
        <mesh filename="meshes/left_shoulder_yaw_link.STL" />
      </geometry>
    </collision>
  </link>
  <joint name="left_shoulder_yaw_joint" type="revolute">
    <origin xyz="-0.016 0 -0.101" rpy="0 0 0" />
    <parent link="left_shoulder_roll_link" />
    <child link="left_shoulder_yaw_link" />
    <axis xyz="0 0 1" />
    <limit lower="-0.8" upper="1.2" effort="15" velocity="30" />
  </joint>
  <link name="left_elbow_link">
    <inertial>
      <origin xyz="0.0914047 0.0199364 -0.0026722" rpy="0 0 0" />
      <mass value="0.3282012" />
      <inertia ixx="0.0003673" ixy="-0.0002004" ixz="-0.0000353" iyy="0.0013996" iyz="0.0000117" izz="0.0014536" />
    </inertial>
    <visual>
      <origin xyz="0 0 0" rpy="0 0 0" />
      <geometry>
        <mesh filename="meshes/left_elbow_link.STL" />
      </geometry>
      <material name="">
        <color rgba="0.89804 0.91765 0.92941 1" />
      </material>
    </visual>
    <collision>
      <origin xyz="0 0 0" rpy="0 0 0" />
      <geometry>
        <mesh filename="meshes/left_elbow_link.STL" />
      </geometry>
    </collision>
  </link>
  <joint name="left_elbow_joint" type="revolute">
    <origin xyz="0 -0.027 -0.149" rpy="0 0 0" />
    <parent link="left_shoulder_yaw_link" />
    <child link="left_elbow_link" />
    <axis xyz="0 1 0" />
    <limit lower="-0.95" upper="1.6" effort="15" velocity="30" />
  </joint>
  <link name="right_shoulder_pitch_link">
    <inertial>
      <origin xyz="-0.0156870 -0.0446137 -0.0003011" rpy="0 0 0" />
      <mass value="0.5474344" />
      <inertia ixx="0.0002167" ixy="-0.0000089" ixz="0.0000002" iyy="0.0001337" iyz="-0.0000007" izz="0.0001874" />
    </inertial>
    <visual>
      <origin xyz="0 0 0" rpy="0 0 0" />
      <geometry>
        <mesh filename="meshes/right_shoulder_pitch_link.STL" />
      </geometry>
      <material name="">
        <color rgba="0.79216 0.81961 0.93333 1" />
      </material>
    </visual>
    <collision>
      <origin xyz="0 0 0" rpy="0 0 0" />
      <geometry>
        <mesh filename="meshes/right_shoulder_pitch_link.STL" />
      </geometry>
    </collision>
  </link>
  <joint name="right_shoulder_pitch_joint" type="revolute">
    <origin xyz="0 -0.1045 0.2905" rpy="0 0 0" />
    <parent link="torso_link" />
    <child link="right_shoulder_pitch_link" />
    <axis xyz="0 1 0" />
    <limit lower="-3.14" upper="1.57" effort="50" velocity="30" />
  </joint>
  <link name="right_shoulder_roll_link">
    <inertial>
      <origin xyz="-0.0127037 -0.0001940 -0.0659292" rpy="0 0 0" />
      <mass value="0.5461248" />
      <inertia ixx="0.0004720" ixy="-0.0000003" ixz="-0.0001010" iyy="0.0004811" iyz="-0.0000016" izz="0.0001598" />
    </inertial>
    <visual>
      <origin xyz="0 0 0" rpy="0 0 0" />
      <geometry>
        <mesh filename="meshes/right_shoulder_roll_link.STL" />
      </geometry>
      <material name="">
        <color rgba="0.79216 0.81961 0.93333 1" />
      </material>
    </visual>
    <collision>
      <origin xyz="0 0 0" rpy="0 0 0" />
      <geometry>
        <mesh filename="meshes/right_shoulder_roll_link.STL" />
      </geometry>
    </collision>
  </link>
  <joint name="right_shoulder_roll_joint" type="revolute">
    <origin xyz="0.01 -0.049 0" rpy="0 0 0" />
    <parent link="right_shoulder_pitch_link" />
    <child link="right_shoulder_roll_link" />
    <axis xyz="1 0 0" />
    <limit lower="-3.4" upper="0.01" effort="15" velocity="30" />
  </joint>
  <link name="right_shoulder_yaw_link">
    <inertial>
      <origin xyz="0.0028726 -0.0002293 -0.1176072" rpy="0 0 0" />
      <mass value="0.7134571" />
      <inertia ixx="0.0020963" ixy="0.0000089" ixz="-0.0000719" iyy="0.0021169" iyz="0.0000175" izz="0.0003397" />
    </inertial>
    <visual>
      <origin xyz="0 0 0" rpy="0 0 0" />
      <geometry>
        <mesh filename="meshes/right_shoulder_yaw_link.STL" />
      </geometry>
      <material name="">
        <color rgba="0.79216 0.81961 0.93333 1" />
      </material>
    </visual>
    <collision>
      <origin xyz="0 0 0" rpy="0 0 0" />
      <geometry>
        <mesh filename="meshes/right_shoulder_yaw_link.STL" />
      </geometry>
    </collision>
  </link>
  <joint name="right_shoulder_yaw_joint" type="revolute">
    <origin xyz="-0.016 0 -0.101" rpy="0 0 0" />
    <parent link="right_shoulder_roll_link" />
    <child link="right_shoulder_yaw_link" />
    <axis xyz="0 0 1" />
    <limit lower="-1.2" upper="0.8" effort="15" velocity="30" />
  </joint>
  <link name="right_elbow_link">
    <inertial>
      <origin xyz="0.0914095 0.0340633 -0.0026701" rpy="0 0 0" />
      <mass value="0.32819" />
      <inertia ixx="0.0003673" ixy="0.0002004" ixz="-0.0000353" iyy="0.0013994" iyz="-0.0000117" izz="0.0014534" />
    </inertial>
    <visual>
      <origin xyz="0 0 0" rpy="0 0 0" />
      <geometry>
        <mesh filename="meshes/right_elbow_link.STL" />
      </geometry>
      <material name="">
        <color rgba="0.89804 0.91765 0.92941 1" />
      </material>
    </visual>
    <collision>
      <origin xyz="0 0 0" rpy="0 0 0" />
      <geometry>
        <mesh filename="meshes/right_elbow_link.STL" />
      </geometry>
    </collision>
  </link>
  <joint name="right_elbow_joint" type="revolute">
    <origin xyz="0 0.027 -0.149" rpy="0 0 0" />
    <parent link="right_shoulder_yaw_link" />
    <child link="right_elbow_link" />
    <axis xyz="0 1 0" />
    <limit lower="-0.95" upper="1.6" effort="15" velocity="30" />
  </joint>
</robot>