<mujoco model="q2">
  <default>
    <default class="robot">
      <default class="motor">
        <joint />
        <motor />
      </default>
      <default class="visual">
        <geom material="visualgeom" contype="0" conaffinity="0" group="2" />
      </default>
      <default class="collision">
        <geom material="collision_material" condim="3" contype="0" conaffinity="1" priority="1" group="1" solref="0.005 1" friction="1 0.01 0.01" />
        <equality solimp="0.99 0.999 1e-05" solref="0.005 1" />
      </default>
    </default>
    <joint damping="0.001" armature="0.01" frictionloss="0.1"/>
  </default>

  <compiler angle="radian" />
  
  <option timestep='0.005' iterations='50' solver='PGS' gravity='0 0 -9.81'>
      <flag frictionloss="enable"/>
  </option>






  <asset>
    <!-- <material name="" rgba="0.89804 0.91765 0.92941 1" /> -->
    <material name="default_material" rgba="0.7 0.7 0.7 1" />
    <material name="collision_material" rgba="1.0 0.28 0.1 0.9" />
    <mesh name="pelvis.STL" file="meshes/pelvis.STL" />
    <mesh name="left_hip_pitch_link.STL" file="meshes/left_hip_pitch_link.STL" />
    <mesh name="left_hip_roll_link.STL" file="meshes/left_hip_roll_link.STL" />
    <mesh name="left_hip_yaw_link.STL" file="meshes/left_hip_yaw_link.STL" />
    <mesh name="left_knee_link.STL" file="meshes/left_knee_link.STL" />
    <mesh name="left_ankle_pitch_link.STL" file="meshes/left_ankle_pitch_link.STL" />
    <mesh name="left_ankle_roll_link.STL" file="meshes/left_ankle_roll_link.STL" />
    <mesh name="right_hip_pitch_link.STL" file="meshes/right_hip_pitch_link.STL" />
    <mesh name="right_hip_roll_link.STL" file="meshes/right_hip_roll_link.STL" />
    <mesh name="right_hip_yaw_link.STL" file="meshes/right_hip_yaw_link.STL" />
    <mesh name="right_knee_link.STL" file="meshes/right_knee_link.STL" />
    <mesh name="right_ankle_pitch_link.STL" file="meshes/right_ankle_pitch_link.STL" />
    <mesh name="right_ankle_roll_link.STL" file="meshes/right_ankle_roll_link.STL" />
    <mesh name="torso_link.STL" file="meshes/torso_link.STL" />
    <mesh name="left_shoulder_pitch_link.STL" file="meshes/left_shoulder_pitch_link.STL" />
    <mesh name="left_shoulder_roll_link.STL" file="meshes/left_shoulder_roll_link.STL" />
    <mesh name="left_shoulder_yaw_link.STL" file="meshes/left_shoulder_yaw_link.STL" />
    <mesh name="left_elbow_link.STL" file="meshes/left_elbow_link.STL" />
    <mesh name="right_shoulder_pitch_link.STL" file="meshes/right_shoulder_pitch_link.STL" />
    <mesh name="right_shoulder_roll_link.STL" file="meshes/right_shoulder_roll_link.STL" />
    <mesh name="right_shoulder_yaw_link.STL" file="meshes/right_shoulder_yaw_link.STL" />
    <mesh name="right_elbow_link.STL" file="meshes/right_elbow_link.STL" />
  </asset>

  <worldbody>
    <body name="pelvis" pos="0.00000000 0.00000000 0.80000" >
        <inertial pos="0.0000000 0.0000000 -0.0377830" quat="1.0 0.0 0.0 0.0" mass="5.0175069" diaginertia="0.0180892 0.016415 0.0108703" />
        <joint name="floating_base_joint" type="free" limited="false" actuatorfrclimited="false"/>
        <geom name="pelvis_collision" pos="0 0 0" quat="1.0 0.0 0.0 0.0" type="mesh" mesh="pelvis.STL" class="collision" />
        <geom name="pelvis_visual" pos="0 0 0" quat="1.0 0.0 0.0 0.0" material="" type="mesh" mesh="pelvis.STL" class="visual" />
        <body name="left_hip_pitch_link" pos="0 0.056 -0.0685" quat="1.0 0.0 0.0 0.0">
          <joint name="left_hip_pitch_joint" type="hinge" ref="0.0" class="motor" range="-2.35 2.35" axis="0 1 0" />
          <inertial pos="-0.0161091 0.0642172 0.0000000" quat="1.0 0.0 0.0 0.0" mass="1.871603" diaginertia="0.0035823 0.0021368 0.0024927" />
          <geom name="left_hip_pitch_link_collision" pos="0 0 0" quat="1.0 0.0 0.0 0.0" type="mesh" mesh="left_hip_pitch_link.STL" class="collision" />
          <geom name="left_hip_pitch_link_visual" pos="0 0 0" quat="1.0 0.0 0.0 0.0" material="" type="mesh" mesh="left_hip_pitch_link.STL" class="visual" />
          <body name="left_hip_roll_link" pos="0.012 0.069 0" quat="1.0 0.0 0.0 0.0">
            <joint name="left_hip_roll_joint" type="hinge" ref="0.0" class="motor" range="-0.43 2.9" axis="1 0 0" />
            <inertial pos="-0.0070439 -0.0000032 -0.0909871" quat="1.0 0.0 0.0 0.0" mass="2.1194499" diaginertia="0.0063862 0.0063266 0.0036912" />
            <geom name="left_hip_roll_link_visual" pos="0 0 0" quat="1.0 0.0 0.0 0.0" material="" type="mesh" mesh="left_hip_roll_link.STL" class="visual" />
            <body name="left_hip_yaw_link" pos="-0.012 0 -0.1395" quat="1.0 0.0 0.0 0.0">
              <joint name="left_hip_yaw_joint" type="hinge" ref="0.0" class="motor" range="-2.8 2.8" axis="0 0 1" />
              <inertial pos="0.0030582 -0.0028146 -0.1280729" quat="1.0 0.0 0.0 0.0" mass="2.4878491" diaginertia="0.0107399 0.0117862 0.003867" />
              <geom name="left_hip_yaw_link_collision" pos="0 0 0" quat="1.0 0.0 0.0 0.0" type="mesh" mesh="left_hip_yaw_link.STL" class="collision" />
              <geom name="left_hip_yaw_link_visual" pos="0 0 0" quat="1.0 0.0 0.0 0.0" material="" type="mesh" mesh="left_hip_yaw_link.STL" class="visual" />
              <body name="left_knee_link" pos="0 0.0255 -0.1605" quat="1.0 0.0 0.0 0.0">
                <joint name="left_knee_joint" type="hinge" ref="0.0" class="motor" range="-0.26 2.05" axis="0 1 0" />
                <inertial pos="0.0016871 -0.0202758 -0.1209121" quat="1.0 0.0 0.0 0.0" mass="2.1687705" diaginertia="0.0161842 0.0144942 0.0039929" />
                <geom name="left_knee_link_visual" pos="0 0 0" quat="1.0 0.0 0.0 0.0" material="" type="mesh" mesh="left_knee_link.STL" class="visual" />
                <body name="left_ankle_pitch_link" pos="0 -0.0255 -0.35" quat="1.0 0.0 0.0 0.0">
                  <joint name="left_ankle_pitch_joint" type="hinge" ref="0.0" class="motor" range="-0.6 0.5" axis="0 1 0" />
                  <inertial pos="0.0000000 0.0000000 0.0000279" quat="1.0 0.0 0.0 0.0" mass="0.0312897" diaginertia="6.8e-06 1.6e-06 7.3e-06" />
                  <geom name="left_ankle_pitch_link_collision" pos="0 0 0" quat="1.0 0.0 0.0 0.0" type="mesh" mesh="left_ankle_pitch_link.STL" class="collision" />
                  <geom name="left_ankle_pitch_link_visual" pos="0 0 0" quat="1.0 0.0 0.0 0.0" material="" type="mesh" mesh="left_ankle_pitch_link.STL" class="visual" />
                  <body name="left_ankle_roll_link" pos="0 0 0" quat="1.0 0.0 0.0 0.0">
                    <joint name="left_ankle_roll_joint" type="hinge" ref="0.0" class="motor" range="-0.25 0.25" axis="1 0 0" />
                    <inertial pos="0.0300502 0.0000000 -0.0348065" quat="1.0 0.0 0.0 0.0" mass="0.445514" diaginertia="0.0001691 0.0007648 0.0007313" />
                    <geom name="left_ankle_roll_link_collision" pos="0 0 0" quat="1.0 0.0 0.0 0.0" type="mesh" mesh="left_ankle_roll_link.STL" class="collision" />
                    <geom name="left_ankle_roll_link_visual" pos="0 0 0" quat="1.0 0.0 0.0 0.0" material="" type="mesh" mesh="left_ankle_roll_link.STL" class="visual" />
                  </body>
                </body>
              </body>
            </body>
          </body>
        </body>
        <body name="right_hip_pitch_link" pos="0 -0.056 -0.0685" quat="1.0 0.0 0.0 0.0">
          <joint name="right_hip_pitch_joint" type="hinge" ref="0.0" class="motor" range="-2.35 2.35" axis="0 1 0" />
          <inertial pos="-0.0161085 -0.0642181 0.0000000" quat="1.0 0.0 0.0 0.0" mass="1.8719556" diaginertia="0.0035829 0.0021371 0.002493" />
          <geom name="right_hip_pitch_link_collision" pos="0 0 0" quat="1.0 0.0 0.0 0.0" type="mesh" mesh="right_hip_pitch_link.STL" class="collision" />
          <geom name="right_hip_pitch_link_visual" pos="0 0 0" quat="1.0 0.0 0.0 0.0" material="" type="mesh" mesh="right_hip_pitch_link.STL" class="visual" />
          <body name="right_hip_roll_link" pos="0.012 -0.069 0" quat="1.0 0.0 0.0 0.0">
            <joint name="right_hip_roll_joint" type="hinge" ref="0.0" class="motor" range="-2.9 0.43" axis="1 0 0" />
            <inertial pos="-0.0070439 -0.0000032 -0.0909871" quat="1.0 0.0 0.0 0.0" mass="2.1194499" diaginertia="0.0063862 0.0063266 0.0036912" />
            <geom name="right_hip_roll_link_visual" pos="0 0 0" quat="1.0 0.0 0.0 0.0" material="" type="mesh" mesh="right_hip_roll_link.STL" class="visual" />
            <body name="right_hip_yaw_link" pos="-0.012 0 -0.1395" quat="1.0 0.0 0.0 0.0">
              <joint name="right_hip_yaw_joint" type="hinge" ref="0.0" class="motor" range="-2.8 2.8" axis="0 0 1" />
              <inertial pos="0.0030618 0.0028152 -0.1281604" quat="1.0 0.0 0.0 0.0" mass="2.4854678" diaginertia="0.0107105 0.0117564 0.0038603" />
              <geom name="right_hip_yaw_link_collision" pos="0 0 0" quat="1.0 0.0 0.0 0.0" type="mesh" mesh="right_hip_yaw_link.STL" class="collision" />
              <geom name="right_hip_yaw_link_visual" pos="0 0 0" quat="1.0 0.0 0.0 0.0" material="" type="mesh" mesh="right_hip_yaw_link.STL" class="visual" />
              <body name="right_knee_link" pos="0 -0.0255 -0.1605" quat="1.0 0.0 0.0 0.0">
                <joint name="right_knee_joint" type="hinge" ref="0.0" class="motor" range="-0.26 2.05" axis="0 1 0" />
                <inertial pos="0.0016703 0.0200408 -0.1207901" quat="1.0 0.0 0.0 0.0" mass="2.1688182" diaginertia="0.0162684 0.0145337 0.0040332" />
                <geom name="right_knee_link_visual" pos="0 0 0" quat="1.0 0.0 0.0 0.0" material="" type="mesh" mesh="right_knee_link.STL" class="visual" />
                <body name="right_ankle_pitch_link" pos="0 0.0255 -0.35" quat="1.0 0.0 0.0 0.0">
                  <joint name="right_ankle_pitch_joint" type="hinge" ref="0.0" class="motor" range="-0.6 0.5" axis="0 1 0" />
                  <inertial pos="0.0000000 0.0000000 0.0000279" quat="1.0 0.0 0.0 0.0" mass="0.0312897" diaginertia="6.8e-06 1.6e-06 7.3e-06" />
                  <geom name="right_ankle_pitch_link_collision" pos="0 0 0" quat="1.0 0.0 0.0 0.0" type="mesh" mesh="right_ankle_pitch_link.STL" class="collision" />
                  <geom name="right_ankle_pitch_link_visual" pos="0 0 0" quat="1.0 0.0 0.0 0.0" material="" type="mesh" mesh="right_ankle_pitch_link.STL" class="visual" />
                  <body name="right_ankle_roll_link" pos="0 0 0" quat="1.0 0.0 0.0 0.0">
                    <joint name="right_ankle_roll_joint" type="hinge" ref="0.0" class="motor" range="-0.25 0.25" axis="1 0 0" />
                    <inertial pos="0.0300502 0.0000000 -0.0348065" quat="1.0 0.0 0.0 0.0" mass="0.445514" diaginertia="0.0001691 0.0007648 0.0007313" />
                    <geom name="right_ankle_roll_link_collision" pos="0 0 0" quat="1.0 0.0 0.0 0.0" type="mesh" mesh="right_ankle_roll_link.STL" class="collision" />
                    <geom name="right_ankle_roll_link_visual" pos="0 0 0" quat="1.0 0.0 0.0 0.0" material="" type="mesh" mesh="right_ankle_roll_link.STL" class="visual" />
                  </body>
                </body>
              </body>
            </body>
          </body>
        </body>
        <body name="torso_link" pos="0 0 0.046" quat="1.0 0.0 0.0 0.0">
          <joint name="torso_joint" type="hinge" ref="0.0" class="motor" range="-1.1 1.1" axis="0 0 1" />
          <inertial pos="0.0004629 -0.0000906 0.1938121" quat="1.0 0.0 0.0 0.0" mass="13.5166565" diaginertia="0.2213687 0.1979885 0.0923944" />
          <geom name="torso_link_collision" pos="0 0 0" quat="1.0 0.0 0.0 0.0" type="mesh" mesh="torso_link.STL" class="collision" />
          <geom name="torso_link_visual" pos="0 0 0" quat="1.0 0.0 0.0 0.0" material="" type="mesh" mesh="torso_link.STL" class="visual" />
          <body name="left_shoulder_pitch_link" pos="0 0.1045 0.2905" quat="1.0 0.0 0.0 0.0">
            <joint name="left_shoulder_pitch_joint" type="hinge" ref="0.0" class="motor" range="-3.14 1.57" axis="0 1 0" />
            <inertial pos="-0.0156870 0.0446137 0.0003011" quat="1.0 0.0 0.0 0.0" mass="0.5474344" diaginertia="0.0002167 0.0001337 0.0001874" />
            <geom name="left_shoulder_pitch_link_collision" pos="0 0 0" quat="1.0 0.0 0.0 0.0" type="mesh" mesh="left_shoulder_pitch_link.STL" class="collision" />
            <geom name="left_shoulder_pitch_link_visual" pos="0 0 0" quat="1.0 0.0 0.0 0.0" material="" type="mesh" mesh="left_shoulder_pitch_link.STL" class="visual" />
            <body name="left_shoulder_roll_link" pos="0.01 0.049 0" quat="1.0 0.0 0.0 0.0">
              <joint name="left_shoulder_roll_joint" type="hinge" ref="0.0" class="motor" range="-0.01 3.14" axis="1 0 0" />
              <inertial pos="-0.0127037 -0.0001940 -0.0659292" quat="1.0 0.0 0.0 0.0" mass="0.5461248" diaginertia="0.000472 0.0004811 0.0001598" />
              <geom name="left_shoulder_roll_link_collision" pos="0 0 0" quat="1.0 0.0 0.0 0.0" type="mesh" mesh="left_shoulder_roll_link.STL" class="collision" />
              <geom name="left_shoulder_roll_link_visual" pos="0 0 0" quat="1.0 0.0 0.0 0.0" material="" type="mesh" mesh="left_shoulder_roll_link.STL" class="visual" />
              <body name="left_shoulder_yaw_link" pos="-0.016 0 -0.101" quat="1.0 0.0 0.0 0.0">
                <joint name="left_shoulder_yaw_joint" type="hinge" ref="0.0" class="motor" range="-0.8 1.2" axis="0 0 1" />
                <inertial pos="0.0032500 0.0002300 -0.1178721" quat="1.0 0.0 0.0 0.0" mass="0.7134352" diaginertia="0.002108 0.002127 0.0003381" />
                <geom name="left_shoulder_yaw_link_collision" pos="0 0 0" quat="1.0 0.0 0.0 0.0" type="mesh" mesh="left_shoulder_yaw_link.STL" class="collision" />
                <geom name="left_shoulder_yaw_link_visual" pos="0 0 0" quat="1.0 0.0 0.0 0.0" material="" type="mesh" mesh="left_shoulder_yaw_link.STL" class="visual" />
                <body name="left_elbow_link" pos="0 -0.027 -0.149" quat="1.0 0.0 0.0 0.0">
                  <joint name="left_elbow_joint" type="hinge" ref="0.0" class="motor" range="-0.95 1.6" axis="0 1 0" />
                  <inertial pos="0.0914047 0.0199364 -0.0026722" quat="1.0 0.0 0.0 0.0" mass="0.3282012" diaginertia="0.0003673 0.0013996 0.0014536" />
                  <geom name="left_elbow_link_collision" pos="0 0 0" quat="1.0 0.0 0.0 0.0" type="mesh" mesh="left_elbow_link.STL" class="collision" />
                  <geom name="left_elbow_link_visual" pos="0 0 0" quat="1.0 0.0 0.0 0.0" material="" type="mesh" mesh="left_elbow_link.STL" class="visual" />
                </body>
              </body>
            </body>
          </body>
          <body name="right_shoulder_pitch_link" pos="0 -0.1045 0.2905" quat="1.0 0.0 0.0 0.0">
            <joint name="right_shoulder_pitch_joint" type="hinge" ref="0.0" class="motor" range="-3.14 1.57" axis="0 1 0" />
            <inertial pos="-0.0156870 -0.0446137 -0.0003011" quat="1.0 0.0 0.0 0.0" mass="0.5474344" diaginertia="0.0002167 0.0001337 0.0001874" />
            <geom name="right_shoulder_pitch_link_collision" pos="0 0 0" quat="1.0 0.0 0.0 0.0" type="mesh" mesh="right_shoulder_pitch_link.STL" class="collision" />
            <geom name="right_shoulder_pitch_link_visual" pos="0 0 0" quat="1.0 0.0 0.0 0.0" material="" type="mesh" mesh="right_shoulder_pitch_link.STL" class="visual" />
            <body name="right_shoulder_roll_link" pos="0.01 -0.049 0" quat="1.0 0.0 0.0 0.0">
              <joint name="right_shoulder_roll_joint" type="hinge" ref="0.0" class="motor" range="-3.4 0.01" axis="1 0 0" />
              <inertial pos="-0.0127037 -0.0001940 -0.0659292" quat="1.0 0.0 0.0 0.0" mass="0.5461248" diaginertia="0.000472 0.0004811 0.0001598" />
              <geom name="right_shoulder_roll_link_collision" pos="0 0 0" quat="1.0 0.0 0.0 0.0" type="mesh" mesh="right_shoulder_roll_link.STL" class="collision" />
              <geom name="right_shoulder_roll_link_visual" pos="0 0 0" quat="1.0 0.0 0.0 0.0" material="" type="mesh" mesh="right_shoulder_roll_link.STL" class="visual" />
              <body name="right_shoulder_yaw_link" pos="-0.016 0 -0.101" quat="1.0 0.0 0.0 0.0">
                <joint name="right_shoulder_yaw_joint" type="hinge" ref="0.0" class="motor" range="-1.2 0.8" axis="0 0 1" />
                <inertial pos="0.0028726 -0.0002293 -0.1176072" quat="1.0 0.0 0.0 0.0" mass="0.7134571" diaginertia="0.0020963 0.0021169 0.0003397" />
                <geom name="right_shoulder_yaw_link_collision" pos="0 0 0" quat="1.0 0.0 0.0 0.0" type="mesh" mesh="right_shoulder_yaw_link.STL" class="collision" />
                <geom name="right_shoulder_yaw_link_visual" pos="0 0 0" quat="1.0 0.0 0.0 0.0" material="" type="mesh" mesh="right_shoulder_yaw_link.STL" class="visual" />
                <body name="right_elbow_link" pos="0 0.027 -0.149" quat="1.0 0.0 0.0 0.0">
                  <joint name="right_elbow_joint" type="hinge" ref="0.0" class="motor" range="-0.95 1.6" axis="0 1 0" />
                  <inertial pos="0.0914095 0.0340633 -0.0026701" quat="1.0 0.0 0.0 0.0" mass="0.32819" diaginertia="0.0003673 0.0013994 0.0014534" />
                  <geom name="right_elbow_link_collision" pos="0 0 0" quat="1.0 0.0 0.0 0.0" type="mesh" mesh="right_elbow_link.STL" class="collision" />
                  <geom name="right_elbow_link_visual" pos="0 0 0" quat="1.0 0.0 0.0 0.0" material="" type="mesh" mesh="right_elbow_link.STL" class="visual" />
                </body>
              </body>
            </body>
          </body>
        </body>
      </body>
  </worldbody>

  <actuator>
    <motor name="left_hip_pitch_joint_ctrl" joint="left_hip_pitch_joint" class="motor" />
    <motor name="left_hip_roll_joint_ctrl" joint="left_hip_roll_joint" class="motor" />
    <motor name="left_hip_yaw_joint_ctrl" joint="left_hip_yaw_joint" class="motor" />
    <motor name="left_knee_joint_ctrl" joint="left_knee_joint" class="motor" />
    <motor name="left_ankle_pitch_joint_ctrl" joint="left_ankle_pitch_joint" class="motor" />
    <motor name="left_ankle_roll_joint_ctrl" joint="left_ankle_roll_joint" class="motor" />
    <motor name="right_hip_pitch_joint_ctrl" joint="right_hip_pitch_joint" class="motor" />
    <motor name="right_hip_roll_joint_ctrl" joint="right_hip_roll_joint" class="motor" />
    <motor name="right_hip_yaw_joint_ctrl" joint="right_hip_yaw_joint" class="motor" />
    <motor name="right_knee_joint_ctrl" joint="right_knee_joint" class="motor" />
    <motor name="right_ankle_pitch_joint_ctrl" joint="right_ankle_pitch_joint" class="motor" />
    <motor name="right_ankle_roll_joint_ctrl" joint="right_ankle_roll_joint" class="motor" />
    <motor name="torso_joint_ctrl" joint="torso_joint" class="motor" />
    <motor name="left_shoulder_pitch_joint_ctrl" joint="left_shoulder_pitch_joint" class="motor" />
    <motor name="left_shoulder_roll_joint_ctrl" joint="left_shoulder_roll_joint" class="motor" />
    <motor name="left_shoulder_yaw_joint_ctrl" joint="left_shoulder_yaw_joint" class="motor" />
    <motor name="left_elbow_joint_ctrl" joint="left_elbow_joint" class="motor" />
    <motor name="right_shoulder_pitch_joint_ctrl" joint="right_shoulder_pitch_joint" class="motor" />
    <motor name="right_shoulder_roll_joint_ctrl" joint="right_shoulder_roll_joint" class="motor" />
    <motor name="right_shoulder_yaw_joint_ctrl" joint="right_shoulder_yaw_joint" class="motor" />
    <motor name="right_elbow_joint_ctrl" joint="right_elbow_joint" class="motor" />
  </actuator>

  <contact>
    <exclude body1="pelvis" body2="left_hip_pitch_link" />
    <exclude body1="left_ankle_pitch_link" body2="left_ankle_roll_link" />
    <exclude body1="pelvis" body2="right_hip_pitch_link" />
    <exclude body1="right_ankle_pitch_link" body2="right_ankle_roll_link" />
    <exclude body1="pelvis" body2="torso_link" />
    <exclude body1="torso_link" body2="left_shoulder_pitch_link" />
    <exclude body1="left_shoulder_pitch_link" body2="left_shoulder_roll_link" />
    <exclude body1="left_shoulder_roll_link" body2="left_shoulder_yaw_link" />
    <exclude body1="left_shoulder_yaw_link" body2="left_elbow_link" />
    <exclude body1="torso_link" body2="right_shoulder_pitch_link" />
    <exclude body1="right_shoulder_pitch_link" body2="right_shoulder_roll_link" />
    <exclude body1="right_shoulder_roll_link" body2="right_shoulder_yaw_link" />
    <exclude body1="right_shoulder_yaw_link" body2="right_elbow_link" />
  </contact>

  <!-- <sensor>
    <framepos name="world_site_pos" objtype="site" objname="world_site" />
    <framequat name="world_site_quat" objtype="site" objname="world_site" />
    <framelinvel name="world_site_linvel" objtype="site" objname="world_site" />
    <frameangvel name="world_site_angvel" objtype="site" objname="world_site" />
    <velocimeter name="world_site_vel" site="world_site" />
  </sensor>
    <asset>
        <texture type="skybox" builtin="flat" rgb1="0 0 0" rgb2="0 0 0" width="512" height="3072"/>
        <texture type="2d" name="groundplane" builtin="checker" mark="edge" rgb1="0.2 0.3 0.4" rgb2="0.1 0.2 0.3" markrgb="0.8 0.8 0.8" width="300" height="300"/>
        <material name="groundplane" texture="groundplane" texuniform="true" texrepeat="5 5" reflectance="0.2"/>
    </asset>
    <worldbody>
      <light pos="1 0 3.5" dir="0 0 -1" directional="true"/>
      <geom contype="15" conaffinity="15"  name="floor" size="0 0 0.05" type="plane" material="groundplane"/>
      <site name="world_site" pos="0 0 0" quat="1 0 0 0" />
      <camera name="front_camera" mode="track" fovy="90.0" quat="4.329780281177467e-17 4.329780281177466e-17 0.7071067811865475 0.7071067811865476" pos="0.0 2.0 0.5" />
      <camera name="side_camera" mode="track" fovy="90.0" quat="-0.5 -0.4999999999999999 0.5 0.5000000000000001" pos="-2.0 0.0 0.5" />
    </worldbody> -->
</mujoco>