<?xml version="1.0" encoding="utf-8"?>
<!-- This URDF was automatically created by SolidWorks to URDF Exporter! Originally created by Stephen Brawner (brawner@gmail.com) 
     Commit Version: 1.6.0-4-g7f85cfe  Build Version: 1.6.7995.38578
     For more information, please see http://wiki.ros.org/sw_urdf_exporter -->
<robot name="q1">
  <mujoco>
    <compiler meshdir="meshes" discardvisual="false" balanceinertia= "true"/>
  </mujoco>
    <!-- [CAUTION] uncomment when convert to mujoco -->
  <!-- <link name="world"></link>
    <joint name="floating_base_joint" type="floating">
      <parent link="world"/>
      <child link="pelvis"/>
  </joint> -->
  <link
    name="pelvis">
    <inertial>
      <origin
        xyz="3.9952E-07 -5.0661E-07 -0.037741"
        rpy="0 0 0" />
      <mass
        value="4.7536" />
      <inertia
     ixx="0.0171677"
        ixy="-1E-07"
        ixz="0"
        iyy="0.0076331"
        iyz="0"
        izz="0.0103668" />
    </inertial>
    <visual>
      <origin
        xyz="0 0 0"
        rpy="0 0 0" />
      <geometry>
        <mesh
          filename="meshes/pelvis.STL" />
      </geometry>
      <material
        name="">
        <color
          rgba="0.75294 0.75294 0.75294 1" />
      </material>
    </visual>
    <collision>
      <origin
        xyz="0 0 0"
        rpy="0 0 0" />
      <geometry>
        <mesh
          filename="meshes/pelvis.STL" />
      </geometry>
    </collision>
  </link>
  <link
    name="left_hip_pitch_link">
    <inertial>
      <origin
        xyz="-0.016351 0.065052 5.0424E-07"
        rpy="0 0 0" />
      <mass
        value="1.8046" />
      <inertia
        ixx="0.0034686"
        ixy="3.65E-05"
        ixz="-1E-07"
        iyy="0.0020662"
        iyz="-2.3E-06"
        izz="0.0024205" />
    </inertial>
    <visual>
      <origin
        xyz="0 0 0"
        rpy="0 0 0" />
      <geometry>
        <mesh
          filename="meshes/left_hip_pitch_link.STL" />
      </geometry>
      <material
        name="">
        <color
          rgba="0.89804 0.91765 0.92941 1" />
      </material>
    </visual>
    <collision>
      <origin
        xyz="0 0 0"
        rpy="0 0 0" />
      <geometry>
        <mesh
          filename="meshes/left_hip_pitch_link.STL" />
      </geometry>
    </collision>
  </link>
  <joint
    name="left_hip_pitch_joint"
    type="revolute">
    <origin
      xyz="0 0.056 -0.0685"
      rpy="0 0 0" />
    <parent
      link="pelvis" />
    <child
      link="left_hip_pitch_link" />
    <axis
      xyz="0 1 0" />
    <limit
      lower="-2.2"
      upper="1.1"
      effort="88"
      velocity="20" />
  </joint>
  <link
    name="left_hip_roll_link">
    <inertial>
      <origin
        xyz="-0.0069071 -3.3359E-06 -0.090328"
        rpy="0 0 0" />
      <mass
        value="2.1115" />
      <inertia
        ixx="0.0065757"
        ixy="2.2E-06"
        ixz="-0.0009257"
        iyy="0.0065179"
        iyz="8E-07"
        izz="0.0036546" />
    </inertial>
    <visual>
      <origin
        xyz="0 0 0"
        rpy="0 0 0" />
      <geometry>
        <mesh
          filename="meshes/left_hip_roll_link.STL" />
      </geometry>
      <material
        name="">
        <color
          rgba="0.11373 0.11373 0.11373 1" />
      </material>
    </visual>
    <!-- <collision>
      <origin
        xyz="0 0 0"
        rpy="0 0 0" />
      <geometry>
        <mesh
          filename="meshes/left_hip_roll_link.STL" />
      </geometry>
    </collision> -->
  </link>
  <joint
    name="left_hip_roll_joint"
    type="revolute">
    <origin
      xyz="0.012 0.069 0"
      rpy="0 0 0" />
    <parent
      link="left_hip_pitch_link" />
    <child
      link="left_hip_roll_link" />
    <axis
      xyz="1 0 0" />
    <limit
      lower="-0.43"
      upper="2.6"
      effort="88"
      velocity="20" />
  </joint>
  <link
    name="left_hip_yaw_link">
    <inertial>
      <origin
        xyz="0.0033205 -0.0029528 -0.12778"
        rpy="0 0 0" />
      <mass
        value="2.3488936" />
      <inertia
        ixx="0.0104385"
        ixy="1.79E-05"
        ixz="-0.0002837"
        iyy="0.0113974"
        iyz="-0.0001584"
        izz="0.003719" />
    </inertial>
    <visual>
      <origin
        xyz="0 0 0"
        rpy="0 0 0" />
      <geometry>
        <mesh
          filename="meshes/left_hip_yaw_link.STL" />
      </geometry>
      <material
        name="">
        <color
          rgba="0.89804 0.91765 0.92941 1" />
      </material>
    </visual>
    <collision>
      <origin
        xyz="0 0 0"
        rpy="0 0 0" />
      <geometry>
        <mesh
          filename="meshes/left_hip_yaw_link.STL" />
      </geometry>
    </collision>
  </link>
  <joint
    name="left_hip_yaw_joint"
    type="revolute">
    <origin
      xyz="-0.012 0 -0.1395"
      rpy="0 0 0" />
    <parent
      link="left_hip_roll_link" />
    <child
      link="left_hip_yaw_link" />
    <axis
      xyz="0 0 1" />
    <limit
      lower="-0.6"
      upper="1"
      effort="88"
      velocity="20" />
  </joint>
  <link
    name="left_knee_link">
    <inertial>
      <origin
        xyz="0.00041557 -0.020195 -0.12173"
        rpy="0 0 0" />
      <mass
        value="2.045647" />
      <inertia
        ixx="0.0159872"
        ixy="6.37E-05"
        ixz="0.0003074"
        iyy="0.0144751"
        iyz="-0.0012435"
        izz="0.0037803" />
    </inertial>
    <visual>
      <origin
        xyz="0 0 0"
        rpy="0 0 0" />
      <geometry>
        <mesh
          filename="meshes/left_knee_link.STL" />
      </geometry>
      <material
        name="">
        <color
          rgba="0.79216 0.81961 0.93333 1" />
      </material>
    </visual>
    <collision>
      <origin
        xyz="0 0 0"
        rpy="0 0 0" />
      <geometry>
        <mesh
          filename="meshes/left_knee_link.STL" />
      </geometry>
    </collision>
  </link>
  <joint
    name="left_knee_joint"
    type="revolute">
    <origin
      xyz="0 0.0255 -0.1605"
      rpy="0 0 0" />
    <parent
      link="left_hip_yaw_link" />
    <child
      link="left_knee_link" />
    <axis
      xyz="0 1 0" />
    <limit
      lower="-0.26"
      upper="2.05"
      effort="100"
      velocity="20" />
  </joint>
  <link
    name="left_ankle_link">
    <inertial>
      <origin
        xyz="0.0257308929278568 1.82942599347147E-07 -0.0315718467212999"
        rpy="0 0 0" />
      <mass
        value="0.3360867 " />
      <inertia
        ixx="0.0001552"
        ixy="0"
        ixz="0.0000664"
        iyy="0.0005830"
        iyz="0"
        izz="0.0005283" />
    </inertial>
    <visual>
      <origin
        xyz="0 0 0"
        rpy="0 0 0" />
      <geometry>
        <mesh
          filename="meshes/left_ankle_link.STL" />
      </geometry>
      <material
        name="">
        <color
          rgba="0.89804 0.91765 0.92941 1" />
      </material>
    </visual>
    <collision>
      <origin
        xyz="0 0 0"
        rpy="0 0 0" />
      <geometry>
        <mesh
          filename="meshes/left_ankle_link.STL" />
      </geometry>
    </collision>
  </link>
  <joint
    name="left_ankle_joint"
    type="revolute">
    <origin
      xyz="0 -0.0255 -0.35"
      rpy="0 0 0" />
    <parent
      link="left_knee_link" />
    <child
      link="left_ankle_link" />
    <axis
      xyz="0 1 0" />
    <limit
      lower="-1"
      upper="1"
      effort="15"
      velocity="20" />
  </joint>
  <link
    name="right_hip_pitch_link">
    <inertial>
      <origin
        xyz="-0.0163510459107585 -0.0650521682520192 -5.63736568870432E-07"
        rpy="0 0 0" />
      <mass
        value="1.7535642703233" />
      <inertia
        ixx="0.00317222224998111"
        ixy="0.000114373128029032"
        ixz="-1.23346018899592E-07"
        iyy="0.00190935361897023"
        iyz="2.34852161745452E-06"
        izz="0.002034654492597" />
    </inertial>
    <visual>
      <origin
        xyz="0 0 0"
        rpy="0 0 0" />
      <geometry>
        <mesh
          filename="meshes/right_hip_pitch_link.STL" />
      </geometry>
      <material
        name="">
        <color
          rgba="0.898039215686275 0.917647058823529 0.929411764705882 1" />
      </material>
    </visual>
    <collision>
      <origin
        xyz="0 0 0"
        rpy="0 0 0" />
      <geometry>
        <mesh
          filename="meshes/right_hip_pitch_link.STL" />
      </geometry>
    </collision>
  </link>
  <joint
    name="right_hip_pitch_joint"
    type="revolute">
    <origin
      xyz="0 -0.056 -0.0685"
      rpy="0 0 0" />
    <parent
      link="pelvis" />
    <child
      link="right_hip_pitch_link" />
    <axis
      xyz="0 1 0" />
    <limit
      lower="-2.2"
      upper="1.1"
      effort="88"
      velocity="20" />
  </joint>
  <link
    name="right_hip_roll_link">
    <inertial>
      <origin
        xyz="-0.0069071 -3.3353E-06 -0.090328"
        rpy="0 0 0" />
      <mass
        value="2.1095097" />
      <inertia
        ixx="0.0065735"
        ixy="2E-07"
        ixz="-0.0009263"
        iyy="0.0065148"
        iyz="-1.2E-06"
        izz="0.0036498" />
    </inertial>
    <visual>
      <origin
        xyz="0 0 0"
        rpy="0 0 0" />
      <geometry>
        <mesh
          filename="meshes/right_hip_roll_link.STL" />
      </geometry>
      <material
        name="">
        <color
          rgba="0.11373 0.11373 0.11373 1" />
      </material>
    </visual>
    <!-- <collision>
      <origin
        xyz="0 0 0"
        rpy="0 0 0" />
      <geometry>
        <mesh
          filename="meshes/right_hip_roll_link.STL" />
      </geometry>
    </collision> -->
  </link>
  <joint
    name="right_hip_roll_joint"
    type="revolute">
    <origin
      xyz="0.012 -0.069 0"
      rpy="0 0 0" />
    <parent
      link="right_hip_pitch_link" />
    <child
      link="right_hip_roll_link" />
    <axis
      xyz="1 0 0" />
    <limit
      lower="-2.6"
      upper="0.43"
      effort="88"
      velocity="20" />
  </joint>
  <link
    name="right_hip_yaw_link">
    <inertial>
      <origin
        xyz="0.003323 0.0029545 -0.12788"
        rpy="0 0 0" />
      <mass
        value="2.346563" />
      <inertia
        ixx="0.01041"
        ixy="-1.78E-05"
        ixz="-0.0002843"
        iyy="0.0113688"
        iyz="0.0001575"
        izz="0.0037124" />
    </inertial>
    <visual>
      <origin
        xyz="0 0 0"
        rpy="0 0 0" />
      <geometry>
        <mesh
          filename="meshes/right_hip_yaw_link.STL" />
      </geometry>
      <material
        name="">
        <color
          rgba="0.89804 0.91765 0.92941 1" />
      </material>
    </visual>
    <collision>
      <origin
        xyz="0 0 0"
        rpy="0 0 0" />
      <geometry>
        <mesh
          filename="meshes/right_hip_yaw_link.STL" />
      </geometry>
    </collision>
  </link>
  <joint
    name="right_hip_yaw_joint"
    type="revolute">
    <origin
      xyz="-0.012 0 -0.1395"
      rpy="0 0 0" />
    <parent
      link="right_hip_roll_link" />
    <child
      link="right_hip_yaw_link" />
    <axis
      xyz="0 0 1" />
    <limit
      lower="-1"
      upper="0.6"
      effort="88"
      velocity="20" />
  </joint>
  <link
    name="right_knee_link">
    <inertial>
      <origin
        xyz="0.00040718 0.01995 -0.12161"
        rpy="0 0 0" />
      <mass
        value="2.0286725" />
      <inertia
        ixx="0.0157884"
        ixy="4.1E-06"
        ixz="0.0003042"
        iyy="0.0142414"
        iyz="0.0013293"
        izz="0.0038062" />
    </inertial>
    <visual>
      <origin
        xyz="0 0 0"
        rpy="0 0 0" />
      <geometry>
        <mesh
          filename="meshes/right_knee_link.STL" />
      </geometry>
      <material
        name="">
        <color
          rgba="0.79216 0.81961 0.93333 1" />
      </material>
    </visual>
    <collision>
      <origin
        xyz="0 0 0"
        rpy="0 0 0" />
      <geometry>
        <mesh
          filename="meshes/right_knee_link.STL" />
      </geometry>
    </collision>
  </link>
  <joint
    name="right_knee_joint"
    type="revolute">
    <origin
      xyz="0 -0.0255 -0.1605"
      rpy="0 0 0" />
    <parent
      link="right_hip_yaw_link" />
    <child
      link="right_knee_link" />
    <axis
      xyz="0 1 0" />
    <limit
      lower="-0.26"
      upper="2.05"
      effort="100"
      velocity="20" />
  </joint>
  <link
    name="right_ankle_link">
    <inertial>
      <origin
        xyz="0.0257308929422537 1.82956781821786E-07 -0.0315718467362111"
        rpy="0 0 0" />
      <mass
        value="0.3340051" />
      <inertia
        ixx="0.0001542"
        ixy="-0.0000014"
        ixz="0.0000655"
        iyy="0.0005796"
        iyz="0.0000004"
        izz="0.0005246" />
    </inertial>
    <visual>
      <origin
        xyz="0 0 0"
        rpy="0 0 0" />
      <geometry>
        <mesh
          filename="meshes/right_ankle_link.STL" />
      </geometry>
      <material
        name="">
        <color
          rgba="0.898039215686275 0.917647058823529 0.929411764705882 1" />
      </material>
    </visual>
    <collision>
      <origin
        xyz="0 0 0"
        rpy="0 0 0" />
      <geometry>
        <mesh
          filename="meshes/right_ankle_link.STL" />
      </geometry>
    </collision>
  </link>
  <joint
    name="right_ankle_joint"
    type="revolute">
    <origin
      xyz="0 0.0255 -0.35"
      rpy="0 0 0" />
    <parent
      link="right_knee_link" />
    <child
      link="right_ankle_link" />
    <axis
      xyz="0 1 0" />
    <limit
      lower="-1"
      upper="1"
      effort="15"
      velocity="20" />
  </joint>
  <link
    name="torso_link">
    <inertial>
      <origin
  xyz="-0.000428 4.1805E-07 0.17682"
        rpy="0 0 0" />
      <mass
        value="13.7367215" />
      <inertia
        ixx="0.2404409"
        ixy="-0.0002466"
        ixz="-0.0027221"
        iyy="0.2185825"
        iyz="0.000136"
        izz="0.0951078" />
    </inertial>
    <visual>
      <origin
        xyz="0 0 0"
        rpy="0 0 0" />
      <geometry>
        <mesh
          filename="meshes/torso_link.STL" />
      </geometry>
      <material
        name="">
        <color
          rgba="0.75294 0.75294 0.75294 1" />
      </material>
    </visual>
    <collision>
      <origin
        xyz="0 0 0"
        rpy="0 0 0" />
      <geometry>
        <mesh
          filename="meshes/torso_link.STL" />
      </geometry>
    </collision>
  </link>
  <joint
    name="torso_joint"
    type="revolute">
    <origin
      xyz="0 0 0.046"
      rpy="0 0 0" />
    <parent
      link="pelvis" />
    <child
      link="torso_link" />
    <axis
      xyz="0 0 1" />
    <limit
      lower="-1.1"
      upper="1.1"
      effort="88"
      velocity="20" />
  </joint>
  <link
    name="left_shoulder_pitch_link">
    <inertial>
      <origin
        xyz="-0.020734 0.034555 0.00012105"
        rpy="0 0 0" />
      <mass
        value="0.5404653" />
      <inertia
        ixx="0.0002377"
        ixy="1.79E-05"
        ixz="-2E-07"
        iyy="0.0001403"
        iyz="-9E-07"
        izz="0.0002119" />
    </inertial>
    <visual>
      <origin
        xyz="0 0 0"
        rpy="0 0 0" />
      <geometry>
        <mesh
          filename="meshes/left_shoulder_pitch_link.STL" />
      </geometry>
      <material
        name="">
        <color
          rgba="0.79216 0.81961 0.93333 1" />
      </material>
    </visual>
    <collision>
      <origin
        xyz="0 0 0"
        rpy="0 0 0" />
      <geometry>
        <mesh
          filename="meshes/left_shoulder_pitch_link.STL" />
      </geometry>
    </collision>
  </link>
  <joint
    name="left_shoulder_pitch_joint"
    type="revolute">
    <origin
      xyz="0 0.1045 0.2905"
      rpy="0 0 0" />
    <parent
      link="torso_link" />
    <child
      link="left_shoulder_pitch_link" />
    <axis
      xyz="0 1 0" />
    <limit
      lower="-3.14"
      upper="1.57"
      effort="50"
      velocity="20" />
  </joint>
  <link
    name="left_shoulder_roll_link">
    <inertial>
      <origin
        xyz="-0.0065007 -0.00036576 -0.038664"
        rpy="0 0 0" />
      <mass
        value="0.5428322" />
      <inertia
        ixx="0.0005318"
        ixy="-1.5E-06"
        ixz="-0.0001104"
        iyy="0.000544"
        iyz="-6.9E-06"
        izz="0.0001672" />
    </inertial>
    <visual>
      <origin
        xyz="0 0 0"
        rpy="0 0 0" />
      <geometry>
        <mesh
          filename="meshes/left_shoulder_roll_link.STL" />
      </geometry>
      <material
        name="">
        <color
          rgba="0.79216 0.81961 0.93333 1" />
      </material>
    </visual>
    <collision>
      <origin
        xyz="0 0 0"
        rpy="0 0 0" />
      <geometry>
        <mesh
          filename="meshes/left_shoulder_roll_link.STL" />
      </geometry>
    </collision>
  </link>
  <joint
    name="left_shoulder_roll_joint"
    type="revolute">
    <origin
      xyz="0.01 0.049 0"
      rpy="0 0 0" />
    <parent
      link="left_shoulder_pitch_link" />
    <child
      link="left_shoulder_roll_link" />
    <axis
      xyz="1 0 0" />
    <limit
      lower="-0.01"
      upper="3.14"
      effort="15"
      velocity="20" />
  </joint>
  <link
    name="left_shoulder_yaw_link">
    <inertial>
      <origin
        xyz="0.0068812 0.0047065 -0.084682"
        rpy="0 0 0" />
      <mass
        value="0.6759657" />
      <inertia
        ixx="0.0018143"
        ixy="8.2E-06"
        ixz="-6.92E-05"
        iyy="0.0018354"
        iyz="1.8E-05"
        izz="0.0003229" />
    </inertial>
    <visual>
      <origin
        xyz="0 0 0"
        rpy="0 0 0" />
      <geometry>
        <mesh
          filename="meshes/left_shoulder_yaw_link.STL" />
      </geometry>
      <material
        name="">
        <color
          rgba="0.79216 0.81961 0.93333 1" />
      </material>
    </visual>
    <collision>
      <origin
        xyz="0 0 0"
        rpy="0 0 0" />
      <geometry>
        <mesh
          filename="meshes/left_shoulder_yaw_link.STL" />
      </geometry>
    </collision>
  </link>
  <joint
    name="left_shoulder_yaw_joint"
    type="revolute">
    <origin
      xyz="-0.016 0 -0.101"
      rpy="0 0 0" />
    <parent
      link="left_shoulder_roll_link" />
    <child
      link="left_shoulder_yaw_link" />
    <axis
      xyz="0 0 1" />
    <limit
      lower="-0.8"
      upper="1.2"
      effort="15"
      velocity="20" />
  </joint>
  <link
    name="left_elbow_link">
    <inertial>
      <origin
        xyz="0.091408 0.019941 -0.0026698"
        rpy="0 0 0" />
      <mass
        value="0.3412209" />
      <inertia
        ixx="0.0003745"
        ixy="0.0002251"
        ixz="-3.22E-05"
        iyy="0.0015061"
        iyz="-1.24E-05"
        izz="0.0015652" />
    </inertial>
    <visual>
      <origin
        xyz="0 0 0"
        rpy="0 0 0" />
      <geometry>
        <mesh
          filename="meshes/left_elbow_link.STL" />
      </geometry>
      <material
        name="">
        <color
          rgba="0.89804 0.91765 0.92941 1" />
      </material>
    </visual>
    <collision>
      <origin
        xyz="0 0 0"
        rpy="0 0 0" />
      <geometry>
        <mesh
          filename="meshes/left_elbow_link.STL" />
      </geometry>
    </collision>
  </link>
  <joint
    name="left_elbow_joint"
    type="revolute">
    <origin
      xyz="0 -0.027 -0.149"
      rpy="0 0 0" />
    <parent
      link="left_shoulder_yaw_link" />
    <child
      link="left_elbow_link" />
    <axis
      xyz="0 1 0" />
    <limit
      lower="-0.95"
      upper="1.6"
      effort="15"
      velocity="20" />
  </joint>
  <link
    name="right_shoulder_pitch_link">
    <inertial>
      <origin
        xyz="-0.020734 -0.034555 -0.00012105"
        rpy="0 0 0" />
      <mass
        value="0.5404653" />
      <inertia
        ixx="0.0002377"
        ixy="1.79E-05"
        ixz="-2E-07"
        iyy="0.0001403"
        iyz="-9E-07"
        izz="0.0002119" />
    </inertial>
    <visual>
      <origin
        xyz="0 0 0"
        rpy="0 0 0" />
      <geometry>
        <mesh
          filename="meshes/right_shoulder_pitch_link.STL" />
      </geometry>
      <material
        name="">
        <color
          rgba="0.79216 0.81961 0.93333 1" />
      </material>
    </visual>
    <collision>
      <origin
        xyz="0 0 0"
        rpy="0 0 0" />
      <geometry>
        <mesh
          filename="meshes/right_shoulder_pitch_link.STL" />
      </geometry>
    </collision>
  </link>
  <joint
    name="right_shoulder_pitch_joint"
    type="revolute">
    <origin
      xyz="0 -0.1045 0.2905"
      rpy="0 0 0" />
    <parent
      link="torso_link" />
    <child
      link="right_shoulder_pitch_link" />
    <axis
      xyz="0 1 0" />
    <limit
      lower="-3.14"
      upper="1.57"
      effort="50"
      velocity="20" />
  </joint>
  <link
    name="right_shoulder_roll_link">
    <inertial>
      <origin
        xyz="-0.0065007 -0.00036576 -0.038664"
        rpy="0 0 0" />
      <mass
        value="0.5428322" />
      <inertia
        ixx="0.0005318"
        ixy="-1.5E-06"
        ixz="-0.0001104"
        iyy="0.000544"
        iyz="-6.9E-06"
        izz="0.0001672" />
    </inertial>
    <visual>
      <origin
        xyz="0 0 0"
        rpy="0 0 0" />
      <geometry>
        <mesh
          filename="meshes/right_shoulder_roll_link.STL" />
      </geometry>
      <material
        name="">
        <color
          rgba="0.79216 0.81961 0.93333 1" />
      </material>
    </visual>
    <collision>
      <origin
        xyz="0 0 0"
        rpy="0 0 0" />
      <geometry>
        <mesh
          filename="meshes/right_shoulder_roll_link.STL" />
      </geometry>
    </collision>
  </link>
  <joint
    name="right_shoulder_roll_joint"
    type="revolute">
    <origin
      xyz="0.01 -0.049 0"
      rpy="0 0 0" />
    <parent
      link="right_shoulder_pitch_link" />
    <child
      link="right_shoulder_roll_link" />
    <axis
      xyz="1 0 0" />
    <limit
      lower="-3.4"
      upper="0.01"
      effort="15"
      velocity="20" />
  </joint>
  <link
    name="right_shoulder_yaw_link">
    <inertial>
      <origin
        xyz="0.0067685 -0.0047145 -0.08462"
        rpy="0 0 0" />
      <mass
        value="0.67597" />
      <inertia
        ixx="0.0018143"
        ixy="8.2E-06"
        ixz="-6.92E-05"
        iyy="0.0018354"
        iyz="1.8E-05"
        izz="0.0003229" />
    </inertial>
    <visual>
      <origin
        xyz="0 0 0"
        rpy="0 0 0" />
      <geometry>
        <mesh
          filename="meshes/right_shoulder_yaw_link.STL" />
      </geometry>
      <material
        name="">
        <color
          rgba="0.79216 0.81961 0.93333 1" />
      </material>
    </visual>
    <collision>
      <origin
        xyz="0 0 0"
        rpy="0 0 0" />
      <geometry>
        <mesh
          filename="meshes/right_shoulder_yaw_link.STL" />
      </geometry>
    </collision>
  </link>
  <joint
    name="right_shoulder_yaw_joint"
    type="revolute">
    <origin
      xyz="-0.016 0 -0.101"
      rpy="0 0 0" />
    <parent
      link="right_shoulder_roll_link" />
    <child
      link="right_shoulder_yaw_link" />
    <axis
      xyz="0 0 1" />
    <limit
      lower="-1.2"
      upper="0.8"
      effort="15"
      velocity="20" />
  </joint>
  <link
    name="right_elbow_link">
    <inertial>
      <origin
        xyz="0.091408 -0.019941 -0.0026722"
        rpy="0 0 0" />
      <mass
        value="0.3412209" />
      <inertia
        ixx="0.0003745"
        ixy="0.0002251"
        ixz="-3.22E-05"
        iyy="0.0015061"
        iyz="-1.24E-05"
        izz="0.0015652" />
    </inertial>
    <visual>
      <origin
        xyz="0 0 0"
        rpy="0 0 0" />
      <geometry>
        <mesh
          filename="meshes/right_elbow_link.STL" />
      </geometry>
      <material
        name="">
        <color
          rgba="0.89804 0.91765 0.92941 1" />
      </material>
    </visual>
    <collision>
      <origin
        xyz="0 0 0"
        rpy="0 0 0" />
      <geometry>
        <mesh
          filename="meshes/right_elbow_link.STL" />
      </geometry>
    </collision>
  </link>
  <joint
    name="right_elbow_joint"
    type="revolute">
    <origin
      xyz="0 0.027 -0.149"
      rpy="0 0 0" />
    <parent
      link="right_shoulder_yaw_link" />
    <child
      link="right_elbow_link" />
    <axis
      xyz="0 1 0" />
    <limit
      lower="-0.95"
      upper="1.6"
      effort="15"
      velocity="20" />
  </joint>
  
</robot>