<mujoco model="q1">
  <default>
    <default class="robot">
      <default class="motor">
        <joint />
        <motor />
      </default>
      <default class="visual">
        <geom material="visualgeom" contype="0" conaffinity="0" group="2" />
      </default>
      <default class="collision">
        <geom material="collision_material" condim="3" contype="0" conaffinity="1" priority="1" group="1" solref="0.005 1" friction="1 0.01 0.01" />
        <equality solimp="0.95 0.95 0.001" solref="0.005 1" />
      </default>
    </default>
    <joint damping="0.001" armature="0.01" frictionloss="0.1"/>
  </default>

  <compiler angle="radian" />
  
  <option timestep='0.005' iterations='50' solver='PGS' gravity='0 0 -9.81'>
      <flag frictionloss="enable"/>
  </option>

  <asset>
    <!-- <material name="" rgba="0.89804 0.91765 0.92941 1" /> -->
    <material name="default_material" rgba="0.7 0.7 0.7 1" />
    <material name="collision_material" rgba="1.0 0.28 0.1 0.9" />
    <mesh name="pelvis.STL" file="meshes/pelvis.STL" />
    <mesh name="left_hip_pitch_link.STL" file="meshes/left_hip_pitch_link.STL" />
    <mesh name="left_hip_roll_link.STL" file="meshes/left_hip_roll_link.STL" />
    <mesh name="left_hip_yaw_link.STL" file="meshes/left_hip_yaw_link.STL" />
    <mesh name="left_knee_link.STL" file="meshes/left_knee_link.STL" />
    <mesh name="left_ankle_link.STL" file="meshes/left_ankle_link.STL" />
    <mesh name="right_hip_pitch_link.STL" file="meshes/right_hip_pitch_link.STL" />
    <mesh name="right_hip_roll_link.STL" file="meshes/right_hip_roll_link.STL" />
    <mesh name="right_hip_yaw_link.STL" file="meshes/right_hip_yaw_link.STL" />
    <mesh name="right_knee_link.STL" file="meshes/right_knee_link.STL" />
    <mesh name="right_ankle_link.STL" file="meshes/right_ankle_link.STL" />
    <mesh name="torso_link.STL" file="meshes/torso_link.STL" />
    <mesh name="left_shoulder_pitch_link.STL" file="meshes/left_shoulder_pitch_link.STL" />
    <mesh name="left_shoulder_roll_link.STL" file="meshes/left_shoulder_roll_link.STL" />
    <mesh name="left_shoulder_yaw_link.STL" file="meshes/left_shoulder_yaw_link.STL" />
    <mesh name="left_elbow_link.STL" file="meshes/left_elbow_link.STL" />
    <mesh name="right_shoulder_pitch_link.STL" file="meshes/right_shoulder_pitch_link.STL" />
    <mesh name="right_shoulder_roll_link.STL" file="meshes/right_shoulder_roll_link.STL" />
    <mesh name="right_shoulder_yaw_link.STL" file="meshes/right_shoulder_yaw_link.STL" />
    <mesh name="right_elbow_link.STL" file="meshes/right_elbow_link.STL" />
  </asset>

  <worldbody>
    <body name="pelvis" pos="0.00000000 0.00000000 0.80000">
        <inertial pos="3.9952E-07 -5.0661E-07 -0.037741" quat="1.0 0.0 0.0 0.0" mass="4.7536" diaginertia="0.0171677 0.0076331 0.0103668" />
        <joint name="floating_base_joint" type="free" limited="false" actuatorfrclimited="false"/>
        <geom name="pelvis_collision" pos="0 0 0" quat="1.0 0.0 0.0 0.0" type="mesh" mesh="pelvis.STL" class="collision" />
        <geom name="pelvis_visual" pos="0 0 0" quat="1.0 0.0 0.0 0.0" material="" type="mesh" mesh="pelvis.STL" class="visual" />
        <body name="left_hip_pitch_link" pos="0 0.056 -0.0685" quat="1.0 0.0 0.0 0.0">
          <joint name="left_hip_pitch_joint" type="hinge" ref="0.0" class="motor" range="-2.2 1.1" axis="0 1 0" />
          <inertial pos="-0.016351 0.065052 5.0424E-07" quat="1.0 0.0 0.0 0.0" mass="1.8046" diaginertia="0.0034686 0.0020662 0.0024205" />
          <geom name="left_hip_pitch_link_collision" pos="0 0 0" quat="1.0 0.0 0.0 0.0" type="mesh" mesh="left_hip_pitch_link.STL" class="collision" />
          <geom name="left_hip_pitch_link_visual" pos="0 0 0" quat="1.0 0.0 0.0 0.0" material="" type="mesh" mesh="left_hip_pitch_link.STL" class="visual" />
          <body name="left_hip_roll_link" pos="0.012 0.069 0" quat="1.0 0.0 0.0 0.0">
            <joint name="left_hip_roll_joint" type="hinge" ref="0.0" class="motor" range="-0.43 2.6" axis="1 0 0" />
            <inertial pos="-0.0069071 -3.3359E-06 -0.090328" quat="1.0 0.0 0.0 0.0" mass="2.1115" diaginertia="0.0065757 0.0065179 0.0036546" />
            <geom name="left_hip_roll_link_visual" pos="0 0 0" quat="1.0 0.0 0.0 0.0" material="" type="mesh" mesh="left_hip_roll_link.STL" class="visual" />
            <body name="left_hip_yaw_link" pos="-0.012 0 -0.1395" quat="1.0 0.0 0.0 0.0">
              <joint name="left_hip_yaw_joint" type="hinge" ref="0.0" class="motor" range="-0.6 1" axis="0 0 1" />
              <inertial pos="0.0033205 -0.0029528 -0.12778" quat="1.0 0.0 0.0 0.0" mass="2.3488936" diaginertia="0.0104385 0.0113974 0.003719" />
              <geom name="left_hip_yaw_link_collision" pos="0 0 0" quat="1.0 0.0 0.0 0.0" type="mesh" mesh="left_hip_yaw_link.STL" class="collision" />
              <geom name="left_hip_yaw_link_visual" pos="0 0 0" quat="1.0 0.0 0.0 0.0" material="" type="mesh" mesh="left_hip_yaw_link.STL" class="visual" />
              <body name="left_knee_link" pos="0 0.0255 -0.1605" quat="1.0 0.0 0.0 0.0">
                <joint name="left_knee_joint" type="hinge" ref="0.0" class="motor" range="-0.26 2.05" axis="0 1 0" />
                <inertial pos="0.00041557 -0.020195 -0.12173" quat="1.0 0.0 0.0 0.0" mass="2.045647" diaginertia="0.0159872 0.0144751 0.0037803" />
                <geom name="left_knee_link_collision" pos="0 0 0" quat="1.0 0.0 0.0 0.0" type="mesh" mesh="left_knee_link.STL" class="collision" />
                <geom name="left_knee_link_visual" pos="0 0 0" quat="1.0 0.0 0.0 0.0" material="" type="mesh" mesh="left_knee_link.STL" class="visual" />
                <body name="left_ankle_link" pos="0 -0.0255 -0.35" quat="1.0 0.0 0.0 0.0">
                  <joint name="left_ankle_joint" type="hinge" ref="0.0" class="motor" range="-1 1" axis="0 1 0" />
                  <inertial pos="0.0257308929278568 1.82942599347147E-07 -0.0315718467212999" quat="1.0 0.0 0.0 0.0" mass="0.3360867 " diaginertia="0.0001552 0.000583 0.0005283" />
                  <geom name="left_ankle_link_collision" pos="0 0 0" quat="1.0 0.0 0.0 0.0" type="mesh" mesh="left_ankle_link.STL" class="collision" />
                  <geom name="left_ankle_link_visual" pos="0 0 0" quat="1.0 0.0 0.0 0.0" material="" type="mesh" mesh="left_ankle_link.STL" class="visual" />
                </body>
              </body>
            </body>
          </body>
        </body>
        <body name="right_hip_pitch_link" pos="0 -0.056 -0.0685" quat="1.0 0.0 0.0 0.0">
          <joint name="right_hip_pitch_joint" type="hinge" ref="0.0" class="motor" range="-2.2 1.1" axis="0 1 0" />
          <inertial pos="-0.0163510459107585 -0.0650521682520192 -5.63736568870432E-07" quat="1.0 0.0 0.0 0.0" mass="1.7535642703233" diaginertia="0.00317222224998111 0.00190935361897023 0.002034654492597" />
          <geom name="right_hip_pitch_link_collision" pos="0 0 0" quat="1.0 0.0 0.0 0.0" type="mesh" mesh="right_hip_pitch_link.STL" class="collision" />
          <geom name="right_hip_pitch_link_visual" pos="0 0 0" quat="1.0 0.0 0.0 0.0" material="" type="mesh" mesh="right_hip_pitch_link.STL" class="visual" />
          <body name="right_hip_roll_link" pos="0.012 -0.069 0" quat="1.0 0.0 0.0 0.0">
            <joint name="right_hip_roll_joint" type="hinge" ref="0.0" class="motor" range="-2.6 0.43" axis="1 0 0" />
            <inertial pos="-0.0069071 -3.3353E-06 -0.090328" quat="1.0 0.0 0.0 0.0" mass="2.1095097" diaginertia="0.0065735 0.0065148 0.0036498" />
            <geom name="right_hip_roll_link_visual" pos="0 0 0" quat="1.0 0.0 0.0 0.0" material="" type="mesh" mesh="right_hip_roll_link.STL" class="visual" />
            <body name="right_hip_yaw_link" pos="-0.012 0 -0.1395" quat="1.0 0.0 0.0 0.0">
              <joint name="right_hip_yaw_joint" type="hinge" ref="0.0" class="motor" range="-1 0.6" axis="0 0 1" />
              <inertial pos="0.003323 0.0029545 -0.12788" quat="1.0 0.0 0.0 0.0" mass="2.346563" diaginertia="0.01041 0.0113688 0.0037124" />
              <geom name="right_hip_yaw_link_collision" pos="0 0 0" quat="1.0 0.0 0.0 0.0" type="mesh" mesh="right_hip_yaw_link.STL" class="collision" />
              <geom name="right_hip_yaw_link_visual" pos="0 0 0" quat="1.0 0.0 0.0 0.0" material="" type="mesh" mesh="right_hip_yaw_link.STL" class="visual" />
              <body name="right_knee_link" pos="0 -0.0255 -0.1605" quat="1.0 0.0 0.0 0.0">
                <joint name="right_knee_joint" type="hinge" ref="0.0" class="motor" range="-0.26 2.05" axis="0 1 0" />
                <inertial pos="0.00040718 0.01995 -0.12161" quat="1.0 0.0 0.0 0.0" mass="2.0286725" diaginertia="0.0157884 0.0142414 0.0038062" />
                <geom name="right_knee_link_collision" pos="0 0 0" quat="1.0 0.0 0.0 0.0" type="mesh" mesh="right_knee_link.STL" class="collision" />
                <geom name="right_knee_link_visual" pos="0 0 0" quat="1.0 0.0 0.0 0.0" material="" type="mesh" mesh="right_knee_link.STL" class="visual" />
                <body name="right_ankle_link" pos="0 0.0255 -0.35" quat="1.0 0.0 0.0 0.0">
                  <joint name="right_ankle_joint" type="hinge" ref="0.0" class="motor" range="-1 1" axis="0 1 0" />
                  <inertial pos="0.0257308929422537 1.82956781821786E-07 -0.0315718467362111" quat="1.0 0.0 0.0 0.0" mass="0.3340051" diaginertia="0.0001542 0.0005796 0.0005246" />
                  <geom name="right_ankle_link_collision" pos="0 0 0" quat="1.0 0.0 0.0 0.0" type="mesh" mesh="right_ankle_link.STL" class="collision" />
                  <geom name="right_ankle_link_visual" pos="0 0 0" quat="1.0 0.0 0.0 0.0" material="" type="mesh" mesh="right_ankle_link.STL" class="visual" />
                </body>
              </body>
            </body>
          </body>
        </body>
        <body name="torso_link" pos="0 0 0.046" quat="1.0 0.0 0.0 0.0">
          <joint name="torso_joint" type="hinge" ref="0.0" class="motor" range="-1.1 1.1" axis="0 0 1" />
          <inertial pos="-0.000428 4.1805E-07 0.17682" quat="1.0 0.0 0.0 0.0" mass="13.7367215" diaginertia="0.2404409 0.2185825 0.0951078" />
          <geom name="torso_link_collision" pos="0 0 0" quat="1.0 0.0 0.0 0.0" type="mesh" mesh="torso_link.STL" class="collision" />
          <geom name="torso_link_visual" pos="0 0 0" quat="1.0 0.0 0.0 0.0" material="" type="mesh" mesh="torso_link.STL" class="visual" />
          <body name="left_shoulder_pitch_link" pos="0 0.1045 0.2905" quat="1.0 0.0 0.0 0.0">
            <joint name="left_shoulder_pitch_joint" type="hinge" ref="0.0" class="motor" range="-3.14 1.57" axis="0 1 0" />
            <inertial pos="-0.020734 0.034555 0.00012105" quat="1.0 0.0 0.0 0.0" mass="0.5404653" diaginertia="0.0002377 0.0001403 0.0002119" />
            <geom name="left_shoulder_pitch_link_collision" pos="0 0 0" quat="1.0 0.0 0.0 0.0" type="mesh" mesh="left_shoulder_pitch_link.STL" class="collision" />
            <geom name="left_shoulder_pitch_link_visual" pos="0 0 0" quat="1.0 0.0 0.0 0.0" material="" type="mesh" mesh="left_shoulder_pitch_link.STL" class="visual" />
            <body name="left_shoulder_roll_link" pos="0.01 0.049 0" quat="1.0 0.0 0.0 0.0">
              <joint name="left_shoulder_roll_joint" type="hinge" ref="0.0" class="motor" range="-0.01 3.14" axis="1 0 0" />
              <inertial pos="-0.0065007 -0.00036576 -0.038664" quat="1.0 0.0 0.0 0.0" mass="0.5428322" diaginertia="0.0005318 0.000544 0.0001672" />
              <geom name="left_shoulder_roll_link_collision" pos="0 0 0" quat="1.0 0.0 0.0 0.0" type="mesh" mesh="left_shoulder_roll_link.STL" class="collision" />
              <geom name="left_shoulder_roll_link_visual" pos="0 0 0" quat="1.0 0.0 0.0 0.0" material="" type="mesh" mesh="left_shoulder_roll_link.STL" class="visual" />
              <body name="left_shoulder_yaw_link" pos="-0.016 0 -0.101" quat="1.0 0.0 0.0 0.0">
                <joint name="left_shoulder_yaw_joint" type="hinge" ref="0.0" class="motor" range="-0.8 1.2" axis="0 0 1" />
                <inertial pos="0.0068812 0.0047065 -0.084682" quat="1.0 0.0 0.0 0.0" mass="0.6759657" diaginertia="0.0018143 0.0018354 0.0003229" />
                <geom name="left_shoulder_yaw_link_collision" pos="0 0 0" quat="1.0 0.0 0.0 0.0" type="mesh" mesh="left_shoulder_yaw_link.STL" class="collision" />
                <geom name="left_shoulder_yaw_link_visual" pos="0 0 0" quat="1.0 0.0 0.0 0.0" material="" type="mesh" mesh="left_shoulder_yaw_link.STL" class="visual" />
                <body name="left_elbow_link" pos="0 -0.027 -0.149" quat="1.0 0.0 0.0 0.0">
                  <joint name="left_elbow_joint" type="hinge" ref="0.0" class="motor" range="-0.95 1.6" axis="0 1 0" />
                  <inertial pos="0.091408 0.019941 -0.0026698" quat="1.0 0.0 0.0 0.0" mass="0.3412209" diaginertia="0.0003745 0.0015061 0.0015652" />
                  <geom name="left_elbow_link_collision" pos="0 0 0" quat="1.0 0.0 0.0 0.0" type="mesh" mesh="left_elbow_link.STL" class="collision" />
                  <geom name="left_elbow_link_visual" pos="0 0 0" quat="1.0 0.0 0.0 0.0" material="" type="mesh" mesh="left_elbow_link.STL" class="visual" />
                </body>
              </body>
            </body>
          </body>
          <body name="right_shoulder_pitch_link" pos="0 -0.1045 0.2905" quat="1.0 0.0 0.0 0.0">
            <joint name="right_shoulder_pitch_joint" type="hinge" ref="0.0" class="motor" range="-3.14 1.57" axis="0 1 0" />
            <inertial pos="-0.020734 -0.034555 -0.00012105" quat="1.0 0.0 0.0 0.0" mass="0.5404653" diaginertia="0.0002377 0.0001403 0.0002119" />
            <geom name="right_shoulder_pitch_link_collision" pos="0 0 0" quat="1.0 0.0 0.0 0.0" type="mesh" mesh="right_shoulder_pitch_link.STL" class="collision" />
            <geom name="right_shoulder_pitch_link_visual" pos="0 0 0" quat="1.0 0.0 0.0 0.0" material="" type="mesh" mesh="right_shoulder_pitch_link.STL" class="visual" />
            <body name="right_shoulder_roll_link" pos="0.01 -0.049 0" quat="1.0 0.0 0.0 0.0">
              <joint name="right_shoulder_roll_joint" type="hinge" ref="0.0" class="motor" range="-3.4 0.01" axis="1 0 0" />
              <inertial pos="-0.0065007 -0.00036576 -0.038664" quat="1.0 0.0 0.0 0.0" mass="0.5428322" diaginertia="0.0005318 0.000544 0.0001672" />
              <geom name="right_shoulder_roll_link_collision" pos="0 0 0" quat="1.0 0.0 0.0 0.0" type="mesh" mesh="right_shoulder_roll_link.STL" class="collision" />
              <geom name="right_shoulder_roll_link_visual" pos="0 0 0" quat="1.0 0.0 0.0 0.0" material="" type="mesh" mesh="right_shoulder_roll_link.STL" class="visual" />
              <body name="right_shoulder_yaw_link" pos="-0.016 0 -0.101" quat="1.0 0.0 0.0 0.0">
                <joint name="right_shoulder_yaw_joint" type="hinge" ref="0.0" class="motor" range="-1.2 0.8" axis="0 0 1" />
                <inertial pos="0.0067685 -0.0047145 -0.08462" quat="1.0 0.0 0.0 0.0" mass="0.67597" diaginertia="0.0018143 0.0018354 0.0003229" />
                <geom name="right_shoulder_yaw_link_collision" pos="0 0 0" quat="1.0 0.0 0.0 0.0" type="mesh" mesh="right_shoulder_yaw_link.STL" class="collision" />
                <geom name="right_shoulder_yaw_link_visual" pos="0 0 0" quat="1.0 0.0 0.0 0.0" material="" type="mesh" mesh="right_shoulder_yaw_link.STL" class="visual" />
                <body name="right_elbow_link" pos="0 0.027 -0.149" quat="1.0 0.0 0.0 0.0">
                  <joint name="right_elbow_joint" type="hinge" ref="0.0" class="motor" range="-0.95 1.6" axis="0 1 0" />
                  <inertial pos="0.091408 -0.019941 -0.0026722" quat="1.0 0.0 0.0 0.0" mass="0.3412209" diaginertia="0.0003745 0.0015061 0.0015652" />
                  <geom name="right_elbow_link_collision" pos="0 0 0" quat="1.0 0.0 0.0 0.0" type="mesh" mesh="right_elbow_link.STL" class="collision" />
                  <geom name="right_elbow_link_visual" pos="0 0 0" quat="1.0 0.0 0.0 0.0" material="" type="mesh" mesh="right_elbow_link.STL" class="visual" />
                </body>
              </body>
            </body>
          </body>
        </body>
     </body>
  </worldbody>

  <actuator>
    <motor name="left_hip_pitch_joint_ctrl" joint="left_hip_pitch_joint" class="motor" />
    <motor name="left_hip_roll_joint_ctrl" joint="left_hip_roll_joint" class="motor" />
    <motor name="left_hip_yaw_joint_ctrl" joint="left_hip_yaw_joint" class="motor" />
    <motor name="left_knee_joint_ctrl" joint="left_knee_joint" class="motor" />
    <motor name="left_ankle_joint_ctrl" joint="left_ankle_joint" class="motor" />
    <motor name="right_hip_pitch_joint_ctrl" joint="right_hip_pitch_joint" class="motor" />
    <motor name="right_hip_roll_joint_ctrl" joint="right_hip_roll_joint" class="motor" />
    <motor name="right_hip_yaw_joint_ctrl" joint="right_hip_yaw_joint" class="motor" />
    <motor name="right_knee_joint_ctrl" joint="right_knee_joint" class="motor" />
    <motor name="right_ankle_joint_ctrl" joint="right_ankle_joint" class="motor" />
    <motor name="torso_joint_ctrl" joint="torso_joint" class="motor" />
    <motor name="left_shoulder_pitch_joint_ctrl" joint="left_shoulder_pitch_joint" class="motor" />
    <motor name="left_shoulder_roll_joint_ctrl" joint="left_shoulder_roll_joint" class="motor" />
    <motor name="left_shoulder_yaw_joint_ctrl" joint="left_shoulder_yaw_joint" class="motor" />
    <motor name="left_elbow_joint_ctrl" joint="left_elbow_joint" class="motor" />
    <motor name="right_shoulder_pitch_joint_ctrl" joint="right_shoulder_pitch_joint" class="motor" />
    <motor name="right_shoulder_roll_joint_ctrl" joint="right_shoulder_roll_joint" class="motor" />
    <motor name="right_shoulder_yaw_joint_ctrl" joint="right_shoulder_yaw_joint" class="motor" />
    <motor name="right_elbow_joint_ctrl" joint="right_elbow_joint" class="motor" />
  </actuator>

  <contact>
    <exclude body1="pelvis" body2="left_hip_pitch_link" />
    <exclude body1="left_hip_yaw_link" body2="left_knee_link" />
    <exclude body1="left_knee_link" body2="left_ankle_link" />
    <exclude body1="pelvis" body2="right_hip_pitch_link" />
    <exclude body1="right_hip_yaw_link" body2="right_knee_link" />
    <exclude body1="right_knee_link" body2="right_ankle_link" />
    <exclude body1="pelvis" body2="torso_link" />
    <exclude body1="torso_link" body2="left_shoulder_pitch_link" />
    <exclude body1="left_shoulder_pitch_link" body2="left_shoulder_roll_link" />
    <exclude body1="left_shoulder_roll_link" body2="left_shoulder_yaw_link" />
    <exclude body1="left_shoulder_yaw_link" body2="left_elbow_link" />
    <exclude body1="torso_link" body2="right_shoulder_pitch_link" />
    <exclude body1="right_shoulder_pitch_link" body2="right_shoulder_roll_link" />
    <exclude body1="right_shoulder_roll_link" body2="right_shoulder_yaw_link" />
    <exclude body1="right_shoulder_yaw_link" body2="right_elbow_link" />
  </contact>

  <!-- <sensor>
    <framepos name="world_site_pos" objtype="site" objname="world_site" />
    <framequat name="world_site_quat" objtype="site" objname="world_site" />
    <framelinvel name="world_site_linvel" objtype="site" objname="world_site" />
    <frameangvel name="world_site_angvel" objtype="site" objname="world_site" />
    <velocimeter name="world_site_vel" site="world_site" />
  </sensor>
  <asset>
    <texture type="skybox" builtin="flat" rgb1="0 0 0" rgb2="0 0 0" width="512" height="3072"/>
    <texture type="2d" name="groundplane" builtin="checker" mark="edge" rgb1="0.2 0.3 0.4" rgb2="0.1 0.2 0.3" markrgb="0.8 0.8 0.8" width="300" height="300"/>
    <material name="groundplane" texture="groundplane" texuniform="true" texrepeat="5 5" reflectance="0.2"/>
  </asset>
  <worldbody>
    <light pos="1 0 3.5" dir="0 0 -1" directional="true"/>
    <geom contype="15" conaffinity="15"  name="floor" size="0 0 0.05" type="plane" material="groundplane"/>
    <site name="world_site" pos="0 0 0" quat="1 0 0 0" />
    <camera name="front_camera" mode="track" fovy="90.0" quat="4.329780281177467e-17 4.329780281177466e-17 0.7071067811865475 0.7071067811865476" pos="0.0 2.0 0.5" />
    <camera name="side_camera" mode="track" fovy="90.0" quat="-0.5 -0.4999999999999999 0.5 0.5000000000000001" pos="-2.0 0.0 0.5" />
  </worldbody> -->
</mujoco>